Workbook
Name CoStarAddress: '[1]Raw Rents'!$AL$4:$AL$999
Name CoStarCity: '[1]Raw Rents'!$AW$4:$AW$999
Name CoStarCount: '[1]Raw Rents'!$AA$4:$AA$999
Name CoStarRent: '[1]Raw Rents'!$AE$4:$AE$999
Name CoStarRentName: '[1]Raw Rents'!$W$4:$W$999
Name CoStarRUBSRent: '[1]Raw Rents'!$AJ$4:$AJ$999
Name CoStarSaleAddress: '[1]Sale Comps'!$Y$3:$Y$100
Name CoStarSaleAvgUnitSize: '[1]Sale Comps'!$BN$3:$BN$100
Name CoStarSaleCity: '[1]Sale Comps'!$Z$3:$Z$100
Name CoStarSaleCompLookup: '[1]Sale Comps'!$W$3:$W$100
Name CoStarSaleDate: '[1]Sale Comps'!$AG$3:$AG$100
Name CoStarSaleName: '[1]Sale Comps'!$BO$3:$BO$100
Name CoStarSalePriceTotal: '[1]Sale Comps'!$AE$3:$AE$100
Name CoStarSaleState: '[1]Sale Comps'!$AA$3:$AA$100
Name CoStarSaleUnits: '[1]Sale Comps'!$AC$3:$AC$100
Name CoStarSaleYearBuilt: '[1]Sale Comps'!$AV$3:$AV$100
Name CoStarSaleZipcodes: '[1]Sale Comps'!$X$3:$X$100
Name CoStarSize: '[1]Raw Rents'!$Z$4:$Z$999
Name CoStarState: '[1]Raw Rents'!$AX$4:$AX$999
Name CoStarUnit: '[1]Raw Rents'!$X$4:$X$999
Name CoStarYearBuilt: '[1]Raw Rents'!$BN$4:$BN$999
Name CoStarZip: '[1]Raw Rents'!$AY$4:$AY$999
Name expandedMonths: [1]Yields!$B$25:$B$384
Name expandedYC: [1]Yields!$C$25:$C$384
Name Filepath: '[1]Agency-Data'!$C$1
Name filesource: [1]Validation!$F$2
Name lookuptype: '[1]Rent Comparison'!$BN$3:$BN$25
Name months_per_period: 12/periods_per_year
Name mpp: 12/ppy
Name nper: term*periods_per_year
Name OrgininationMax: '[1]Agency Loan-Sale Comps'!$F$5
Name OriginationMin: '[1]Agency Loan-Sale Comps'!$F$4
Name periods: yrs*ppy
Name PriorCapRateOriginMax: '[1]Agency Loan-Sale Comps'!#REF!
Name PriorCapRateOriginMin: '[1]Agency Loan-Sale Comps'!#REF!
Name PropertySizeMax: '[1]Agency Loan-Sale Comps'!$J$5
Name PropertySizeMin: '[1]Agency Loan-Sale Comps'!$J$4
Name QueryRegion: '[1]Agency Loan-Sale Comps'!$S$3
Name rediq_address1: [1]Master!$B$2
Name rediq_city: [1]Master!$B$3
Name rediq_dealname: [1]Master!$B$1
Name rediq_state: [1]Master!$C$3
Name rediq_zip: [1]Master!$D$3
Name reflink: [1]MasterDealList!$BH$4
Name RegionOriginMax: '[1]Agency Loan-Sale Comps'!$U$5
Name RegionOriginMin: '[1]Agency Loan-Sale Comps'!$U$4
Name RegionSizeMax: '[1]Agency Loan-Sale Comps'!$Y$5
Name RegionSizeMin: '[1]Agency Loan-Sale Comps'!$Y$4
Name RegionYearMax: '[1]Agency Loan-Sale Comps'!$W$5
Name RegionYearMin: '[1]Agency Loan-Sale Comps'!$W$4
Name rrInPlaceRent: '[1]redIQ RR'!$L$9:$L$2000
Name rrMarketRent: '[1]redIQ RR'!$K$9:$K$2000
Name rrUnitBathCount: '[1]redIQ RR'!$G$9:$G$2000
Name rrUnitBedCount: '[1]redIQ RR'!$F$9:$F$2000
Name rrUnitFloorPlan: '[1]redIQ RR'!$D$9:$D$2000
Name rrUnitSF: '[1]redIQ RR'!$E$9:$E$2000
Name valuevx: 42.314159
Name YardiAddress: '[1]Raw Rents'!$E$4:$E$999
Name YardiCity: '[1]Raw Rents'!$F$4:$F$999
Name YardiCount: '[1]Raw Rents'!$N$4:$N$999

Sheet Comparable Grid
L1: DATA SOURCE: | M1: Automatic | N1: Primary Source | AF1: Dropdown Validation:
L2: Include (x) | M2: Comment | N2: Primary Source | O2: Property Name | P2: Base $/Unit | Q2: Address | R2: City | S2: State | T2: Zip | U2: # Units | V2: Distance (miles) | W2: Avg. Unit Size | X2: Year Built | Y2: Sale Price | Z2: Sale Date | AA2: Agency Pricing Data | AB2: CoStar Pricing Data | AC2: Yardi Pricing Data | AD2: Lookup Hook | AE2: helper ref | AG2: Exterior Quality: | AH2: Rank | AJ2: Amenity | AK2: Rank | AM2: Interior | AN2: Rank | AP2: Location | AQ2: Rank
L3: x | M3: =IF($M$1="Manual",IF(Y3="","No Sale Price Disclosed!",""),"") | N3: {=IF($M$1="Manual",IF(AA3<>"","Freddie/Fannie",IF(AB3<>"","CoStar",IF(AC3<>"","Yardi","N/A"))),INDEX([1]!Output_Analysis_Data__2[Info Source],ROW()-2))} -> Yardi | O3: {=IF($M$1="Manual",'[1]Sale Comps'!BY3,INDEX([1]!Output_Analysis_Data__2[Property Name],ROW()-2))} -> Wind Rush | P3: =IFERROR(Y3/U3,"") -> 111510.79 | Q3: {=IF($M$1="Manual",IFERROR(INDEX(CoStarSaleAddress,MATCH(O3,CoStarSaleName,0)),INDEX(YardiSaleAddress,MATCH(O3,YardiSaleName,0))),INDEX([1]!Output_Analysis_Data__2[Property Address],ROW()-2))} -> 3500 Renzel Blvd | R3: {=IF($M$1="Manual",IFERROR(INDEX(CoStarSaleCity,MATCH(O3,CoStarSaleName,0)),INDEX(YardiSaleCity,MATCH(O3,YardiSaleName,0))),INDEX([1]!Output_Analysis_Data__2[City],ROW()-2))} -> Fort Worth | S3: {=IF($M$1="Manual",IFERROR(INDEX(CoStarSaleState,MATCH(O3,CoStarSaleName,0)),INDEX(YardiSaleState,MATCH(O3,YardiSaleName,0))),INDEX([1]!Output_Analysis_Data__2[State],ROW()-2))} -> TX | T3: {=IF($M$1="Manual",IFERROR(INDEX(CoStarSaleZipcodes,MATCH(O3,CoStarSaleName,0)),INDEX(YardiSaleZipcodes,MATCH(O3,YardiSaleName,0))),INDEX([1]!Output_Analysis_Data__2[ZIP],ROW()-2))} -> 76116 | U3: {=IF($M$1="Manual",IFERROR(INDEX(CoStarSaleUnits,MATCH(O3,CoStarSaleName,0)),INDEX(YardiSaleUnits,MATCH(O3,YardiSaleName,0))),INDEX([1]!Output_Analysis_Data__2[Unit Count],ROW()-2))} -> 278 | V3: {=IF($M$1="Manual","",INDEX([1]!Output_Analysis_Data__2[Distance (mi.)],ROW()-2))} -> 1.7223775 | W3: {=IF($M$1="Manual",IFERROR(INDEX(CoStarSaleAvgUnitSize,MATCH(O3,CoStarSaleName,0)),INDEX(YardiSaleAvgUnitSize,MATCH(O3,YardiSaleName,0))),INDEX([1]!Output_Analysis_Data__2[Avg Unit SF],ROW()-2))} -> 799 | X3: {=IF($M$1="Manual",IFERROR(INDEX(CoStarSaleYearBuilt,MATCH(O3,CoStarSaleName,0)),INDEX(YardiSaleYearBuilt,MATCH(O3,YardiSaleName,0))),INDEX([1]!Output_Analysis_Data__2[Year Built],ROW()-2))} -> 1984 | Y3: {=IF($M$1="Manual",IF(AA3<>"",AA3,IF(AB3<>"",AB3,IF(AC3<>"",AC3,""))),INDEX([1]!Output_Analysis_Data__2[Sold Price],ROW()-2))} -> 31000000 | Z3: {=IF($M$1="Manual",IFERROR(INDEX(CoStarSaleDate,MATCH(O3,CoStarSaleName,0)),INDEX(YardiSaleDate,MATCH(O3,YardiSaleName,0))),INDEX([1]!Output_Analysis_Data__2[Sale Date],ROW()-2))} -> 45849 | AA3: =IFERROR(INDEX('[1]Agency Loan-Sale Comps'!$J$16:$J$37,MATCH('Comparable Grid'!AD3,'[1]Agency Loan-Sale Comps'!$A$16:$A$37,0),0),"") | AB3: =IFERROR(IF(INDEX(CoStarSalePriceTotal,MATCH(AD3,CoStarSaleCompLookup,0),0)=0,"",INDEX(CoStarSalePriceTotal,MATCH(AD3,CoStarSaleCompLookup,0),0)),"") | AC3: =IFERROR(IF(INDEX(YardiSalePriceTotal,MATCH(AD3,YardiSaleCompLookup,0),0)=0,"",INDEX(YardiSalePriceTotal,MATCH(AD3,YardiSaleCompLookup,0),0)),"") | AD3: =LEFT(Q3,FIND(" ",Q3,1)) -> 3500 | AE3: =IF($L3="x","x","") -> x | AG3: Deminished | AH3: 1 | AJ3: Inferior | AK3: 1 | AM3: Basic | AN3: 1 | AP3: Below Average | AQ3: 1
L4: x | M4: =IF($M$1="Manual",IF(Y4="","No Sale Price Disclosed!",""),"") | N4: {=IF($M$1="Manual",IF(AA4<>"","Freddie/Fannie",IF(AB4<>"","CoStar",IF(AC4<>"","Yardi","N/A"))),INDEX([1]!Output_Analysis_Data__2[Info Source],ROW()-2))} -> Yardi | O4: {=IF($M$1="Manual",'[1]Sale Comps'!BY4,INDEX([1]!Output_Analysis_Data__2[Property Name],ROW()-2))} -> Falls & Oak Village, The | P4: =IFERROR(Y4/U4,"") -> 101414.63 | Q4: {=IF($M$1="Manual",IFERROR(INDEX(CoStarSaleAddress,MATCH(O4,CoStarSaleName,0)),INDEX(YardiSaleAddress,MATCH(O4,YardiSaleName,0))),INDEX([1]!Output_Analysis_Data__2[Property Address],ROW()-2))} -> 9001 South Normandale Street | R4: {=IF($M$1="Manual",IFERROR(INDEX(CoStarSaleCity,MATCH(O4,CoStarSaleName,0)),INDEX(YardiSaleCity,MATCH(O4,YardiSaleName,0))),INDEX([1]!Output_Analysis_Data__2[City],ROW()-2))} -> Fort Worth | S4: {=IF($M$1="Manual",IFERROR(INDEX(CoStarSaleState,MATCH(O4,CoStarSaleName,0)),INDEX(YardiSaleState,MATCH(O4,YardiSaleName,0))),INDEX([1]!Output_Analysis_Data__2[State],ROW()-2))} -> TX | T4: {=IF($M$1="Manual",IFERROR(INDEX(CoStarSaleZipcodes,MATCH(O4,CoStarSaleName,0)),INDEX(YardiSaleZipcodes,MATCH(O4,YardiSaleName,0))),INDEX([1]!Output_Analysis_Data__2[ZIP],ROW()-2))} -> 76116 | U4: {=IF($M$1="Manual",IFERROR(INDEX(CoStarSaleUnits,MATCH(O4,CoStarSaleName,0)),INDEX(YardiSaleUnits,MATCH(O4,YardiSaleName,0))),INDEX([1]!Output_Analysis_Data__2[Unit Count],ROW()-2))} -> 410 | V4: {=IF($M$1="Manual","",INDEX([1]!Output_Analysis_Data__2[Distance (mi.)],ROW()-2))} -> 1.963263 | W4: {=IF($M$1="Manual",IFERROR(INDEX(CoStarSaleAvgUnitSize,MATCH(O4,CoStarSaleName,0)),INDEX(YardiSaleAvgUnitSize,MATCH(O4,YardiSaleName,0))),INDEX([1]!Output_Analysis_Data__2[Avg Unit SF],ROW()-2))} -> 878 | X4: {=IF($M$1="Manual",IFERROR(INDEX(CoStarSaleYearBuilt,MATCH(O4,CoStarSaleName,0)),INDEX(YardiSaleYearBuilt,MATCH(O4,YardiSaleName,0))),INDEX([1]!Output_Analysis_Data__2[Year Built],ROW()-2))} -> 1974 | Y4: {=IF($M$1="Manual",IF(AA4<>"",AA4,IF(AB4<>"",AB4,IF(AC4<>"",AC4,""))),INDEX([1]!Output_Analysis_Data__2[Sold Price],ROW()-2))} -> 41580000 | Z4: {=IF($M$1="Manual",IFERROR(INDEX(CoStarSaleDate,MATCH(O4,CoStarSaleName,0)),INDEX(YardiSaleDate,MATCH(O4,YardiSaleName,0))),INDEX([1]!Output_Analysis_Data__2[Sale Date],ROW()-2))} -> 45702 | AA4: =IFERROR(INDEX('[1]Agency Loan-Sale Comps'!$J$16:$J$37,MATCH('Comparable Grid'!AD4,'[1]Agency Loan-Sale Comps'!$A$16:$A$37,0),0),"") | AB4: =IFERROR(IF(INDEX(CoStarSalePriceTotal,MATCH(AD4,CoStarSaleCompLookup,0),0)=0,"",INDEX(CoStarSalePriceTotal,MATCH(AD4,CoStarSaleCompLookup,0),0)),"") | AC4: =IFERROR(IF(INDEX(YardiSalePriceTotal,MATCH(AD4,YardiSaleCompLookup,0),0)=0,"",INDEX(YardiSalePriceTotal,MATCH(AD4,YardiSaleCompLookup,0),0)),"") | AD4: =LEFT(Q4,FIND(" ",Q4,1)) -> 9001 | AE4: =AE3&IF($L4="x","x","") -> xx | AG4: Inferior | AH4: 2 | AJ4: Average | AK4: 2 | AM4: Basic+ | AN4: 2 | AP4: Average | AQ4: 2
C5: =rediq_dealname -> Benbrook Apartments | L5: x | M5: =IF($M$1="Manual",IF(Y5="","No Sale Price Disclosed!",""),"") | N5: {=IF($M$1="Manual",IF(AA5<>"","Freddie/Fannie",IF(AB5<>"","CoStar",IF(AC5<>"","Yardi","N/A"))),INDEX([1]!Output_Analysis_Data__2[Info Source],ROW()-2))} -> Fannie | O5: {=IF($M$1="Manual",'[1]Sale Comps'!BY5,INDEX([1]!Output_Analysis_Data__2[Property Name],ROW()-2))} -> Range, The | P5: =IFERROR(Y5/U5,"") -> 105729.17 | Q5: {=IF($M$1="Manual",IFERROR(INDEX(CoStarSaleAddress,MATCH(O5,CoStarSaleName,0)),INDEX(YardiSaleAddress,MATCH(O5,YardiSaleName,0))),INDEX([1]!Output_Analysis_Data__2[Property Address],ROW()-2))} -> 2925 West Normandale Street | R5: {=IF($M$1="Manual",IFERROR(INDEX(CoStarSaleCity,MATCH(O5,CoStarSaleName,0)),INDEX(YardiSaleCity,MATCH(O5,YardiSaleName,0))),INDEX([1]!Output_Analysis_Data__2[City],ROW()-2))} -> Fort Worth | S5: {=IF($M$1="Manual",IFERROR(INDEX(CoStarSaleState,MATCH(O5,CoStarSaleName,0)),INDEX(YardiSaleState,MATCH(O5,YardiSaleName,0))),INDEX([1]!Output_Analysis_Data__2[State],ROW()-2))} -> TX | T5: {=IF($M$1="Manual",IFERROR(INDEX(CoStarSaleZipcodes,MATCH(O5,CoStarSaleName,0)),INDEX(YardiSaleZipcodes,MATCH(O5,YardiSaleName,0))),INDEX([1]!Output_Analysis_Data__2[ZIP],ROW()-2))} -> 76116 | U5: {=IF($M$1="Manual",IFERROR(INDEX(CoStarSaleUnits,MATCH(O5,CoStarSaleName,0)),INDEX(YardiSaleUnits,MATCH(O5,YardiSaleName,0))),INDEX([1]!Output_Analysis_Data__2[Unit Count],ROW()-2))} -> 192 | V5: {=IF($M$1="Manual","",INDEX([1]!Output_Analysis_Data__2[Distance (mi.)],ROW()-2))} -> 2.3073797 | W5: {=IF($M$1="Manual",IFERROR(INDEX(CoStarSaleAvgUnitSize,MATCH(O5,CoStarSaleName,0)),INDEX(YardiSaleAvgUnitSize,MATCH(O5,YardiSaleName,0))),INDEX([1]!Output_Analysis_Data__2[Avg Unit SF],ROW()-2))} -> 815 | X5: {=IF($M$1="Manual",IFERROR(INDEX(CoStarSaleYearBuilt,MATCH(O5,CoStarSaleName,0)),INDEX(YardiSaleYearBuilt,MATCH(O5,YardiSaleName,0))),INDEX([1]!Output_Analysis_Data__2[Year Built],ROW()-2))} -> 1985 | Y5: {=IF($M$1="Manual",IF(AA5<>"",AA5,IF(AB5<>"",AB5,IF(AC5<>"",AC5,""))),INDEX([1]!Output_Analysis_Data__2[Sold Price],ROW()-2))} -> 20300000 | Z5: {=IF($M$1="Manual",IFERROR(INDEX(CoStarSaleDate,MATCH(O5,CoStarSaleName,0)),INDEX(YardiSaleDate,MATCH(O5,YardiSaleName,0))),INDEX([1]!Output_Analysis_Data__2[Sale Date],ROW()-2))} -> 45183 | AA5: =IFERROR(INDEX('[1]Agency Loan-Sale Comps'!$J$16:$J$37,MATCH('Comparable Grid'!AD5,'[1]Agency Loan-Sale Comps'!$A$16:$A$37,0),0),"") -> 20300000 | AB5: =IFERROR(IF(INDEX(CoStarSalePriceTotal,MATCH(AD5,CoStarSaleCompLookup,0),0)=0,"",INDEX(CoStarSalePriceTotal,MATCH(AD5,CoStarSaleCompLookup,0),0)),"") | AC5: =IFERROR(IF(INDEX(YardiSalePriceTotal,MATCH(AD5,YardiSaleCompLookup,0),0)=0,"",INDEX(YardiSalePriceTotal,MATCH(AD5,YardiSaleCompLookup,0),0)),"") | AD5: =LEFT(Q5,FIND(" ",Q5,1)) -> 2925 | AE5: =AE4&IF($L5="x","x","") -> xxx | AG5: Average | AH5: 3 | AJ5: Superior | AK5: 3 | AM5: Renovated- | AN5: 3 | AP5: Above Average | AQ5: 3
C6: Comparable Sale Analysis | M6: =IF($M$1="Manual",IF(Y6="","No Sale Price Disclosed!",""),"") | N6: {=IF($M$1="Manual",IF(AA6<>"","Freddie/Fannie",IF(AB6<>"","CoStar",IF(AC6<>"","Yardi","N/A"))),INDEX([1]!Output_Analysis_Data__2[Info Source],ROW()-2))} -> CoStar | O6: {=IF($M$1="Manual",'[1]Sale Comps'!BY6,INDEX([1]!Output_Analysis_Data__2[Property Name],ROW()-2))} -> 9519 Westpark Dr | P6: =IFERROR(Y6/U6,"") -> 136250 | Q6: {=IF($M$1="Manual",IFERROR(INDEX(CoStarSaleAddress,MATCH(O6,CoStarSaleName,0)),INDEX(YardiSaleAddress,MATCH(O6,YardiSaleName,0))),INDEX([1]!Output_Analysis_Data__2[Property Address],ROW()-2))} -> 9519 Westpark Dr | R6: {=IF($M$1="Manual",IFERROR(INDEX(CoStarSaleCity,MATCH(O6,CoStarSaleName,0)),INDEX(YardiSaleCity,MATCH(O6,YardiSaleName,0))),INDEX([1]!Output_Analysis_Data__2[City],ROW()-2))} -> Benbrook | S6: {=IF($M$1="Manual",IFERROR(INDEX(CoStarSaleState,MATCH(O6,CoStarSaleName,0)),INDEX(YardiSaleState,MATCH(O6,YardiSaleName,0))),INDEX([1]!Output_Analysis_Data__2[State],ROW()-2))} -> TX | T6: {=IF($M$1="Manual",IFERROR(INDEX(CoStarSaleZipcodes,MATCH(O6,CoStarSaleName,0)),INDEX(YardiSaleZipcodes,MATCH(O6,YardiSaleName,0))),INDEX([1]!Output_Analysis_Data__2[ZIP],ROW()-2))} -> 76126 | U6: {=IF($M$1="Manual",IFERROR(INDEX(CoStarSaleUnits,MATCH(O6,CoStarSaleName,0)),INDEX(YardiSaleUnits,MATCH(O6,YardiSaleName,0))),INDEX([1]!Output_Analysis_Data__2[Unit Count],ROW()-2))} -> 4 | V6: {=IF($M$1="Manual","",INDEX([1]!Output_Analysis_Data__2[Distance (mi.)],ROW()-2))} -> 2.6028107 | W6: {=IF($M$1="Manual",IFERROR(INDEX(CoStarSaleAvgUnitSize,MATCH(O6,CoStarSaleName,0)),INDEX(YardiSaleAvgUnitSize,MATCH(O6,YardiSaleName,0))),INDEX([1]!Output_Analysis_Data__2[Avg Unit SF],ROW()-2))} -> 0 | X6: {=IF($M$1="Manual",IFERROR(INDEX(CoStarSaleYearBuilt,MATCH(O6,CoStarSaleName,0)),INDEX(YardiSaleYearBuilt,MATCH(O6,YardiSaleName,0))),INDEX([1]!Output_Analysis_Data__2[Year Built],ROW()-2))} -> 1982 | Y6: {=IF($M$1="Manual",IF(AA6<>"",AA6,IF(AB6<>"",AB6,IF(AC6<>"",AC6,""))),INDEX([1]!Output_Analysis_Data__2[Sold Price],ROW()-2))} -> 545000 | Z6: {=IF($M$1="Manual",IFERROR(INDEX(CoStarSaleDate,MATCH(O6,CoStarSaleName,0)),INDEX(YardiSaleDate,MATCH(O6,YardiSaleName,0))),INDEX([1]!Output_Analysis_Data__2[Sale Date],ROW()-2))} -> 45663 | AA6: =IFERROR(INDEX('[1]Agency Loan-Sale Comps'!$J$16:$J$37,MATCH('Comparable Grid'!AD6,'[1]Agency Loan-Sale Comps'!$A$16:$A$37,0),0),"") | AB6: =IFERROR(IF(INDEX(CoStarSalePriceTotal,MATCH(AD6,CoStarSaleCompLookup,0),0)=0,"",INDEX(CoStarSalePriceTotal,MATCH(AD6,CoStarSaleCompLookup,0),0)),"") | AC6: =IFERROR(IF(INDEX(YardiSalePriceTotal,MATCH(AD6,YardiSaleCompLookup,0),0)=0,"",INDEX(YardiSalePriceTotal,MATCH(AD6,YardiSaleCompLookup,0),0)),"") | AD6: =LEFT(Q6,FIND(" ",Q6,1)) -> 9519 | AE6: =AE5&IF($L6="x","x","") -> xxx | AG6: Superior | AH6: 4 | AM6: Renovated | AN6: 4
D7: Subject | E7: =IF(E8="","","Comp 1") -> Comp 1 | F7: =IF(F8="","","Comp 2") -> Comp 2 | G7: =IF(G8="","","Comp 3") -> Comp 3 | H7: =IF(H8="","","Comp 4") -> Comp 4 | I7: =IF(I8="","","Comp 5") -> Comp 5 | M7: =IF($M$1="Manual",IF(Y7="","No Sale Price Disclosed!",""),"") | N7: {=IF($M$1="Manual",IF(AA7<>"","Freddie/Fannie",IF(AB7<>"","CoStar",IF(AC7<>"","Yardi","N/A"))),INDEX([1]!Output_Analysis_Data__2[Info Source],ROW()-2))} -> CoStar | O7: {=IF($M$1="Manual",'[1]Sale Comps'!BY7,INDEX([1]!Output_Analysis_Data__2[Property Name],ROW()-2))} -> 209 Vista Way | P7: =IFERROR(Y7/U7,"") -> 130000 | Q7: {=IF($M$1="Manual",IFERROR(INDEX(CoStarSaleAddress,MATCH(O7,CoStarSaleName,0)),INDEX(YardiSaleAddress,MATCH(O7,YardiSaleName,0))),INDEX([1]!Output_Analysis_Data__2[Property Address],ROW()-2))} -> 209 Vista Way | R7: {=IF($M$1="Manual",IFERROR(INDEX(CoStarSaleCity,MATCH(O7,CoStarSaleName,0)),INDEX(YardiSaleCity,MATCH(O7,YardiSaleName,0))),INDEX([1]!Output_Analysis_Data__2[City],ROW()-2))} -> Benbrook | S7: {=IF($M$1="Manual",IFERROR(INDEX(CoStarSaleState,MATCH(O7,CoStarSaleName,0)),INDEX(YardiSaleState,MATCH(O7,YardiSaleName,0))),INDEX([1]!Output_Analysis_Data__2[State],ROW()-2))} -> TX | T7: {=IF($M$1="Manual",IFERROR(INDEX(CoStarSaleZipcodes,MATCH(O7,CoStarSaleName,0)),INDEX(YardiSaleZipcodes,MATCH(O7,YardiSaleName,0))),INDEX([1]!Output_Analysis_Data__2[ZIP],ROW()-2))} -> 76126 | U7: {=IF($M$1="Manual",IFERROR(INDEX(CoStarSaleUnits,MATCH(O7,CoStarSaleName,0)),INDEX(YardiSaleUnits,MATCH(O7,YardiSaleName,0))),INDEX([1]!Output_Analysis_Data__2[Unit Count],ROW()-2))} -> 4 | V7: {=IF($M$1="Manual","",INDEX([1]!Output_Analysis_Data__2[Distance (mi.)],ROW()-2))} -> 2.6740048 | W7: {=IF($M$1="Manual",IFERROR(INDEX(CoStarSaleAvgUnitSize,MATCH(O7,CoStarSaleName,0)),INDEX(YardiSaleAvgUnitSize,MATCH(O7,YardiSaleName,0))),INDEX([1]!Output_Analysis_Data__2[Avg Unit SF],ROW()-2))} -> 995 | X7: {=IF($M$1="Manual",IFERROR(INDEX(CoStarSaleYearBuilt,MATCH(O7,CoStarSaleName,0)),INDEX(YardiSaleYearBuilt,MATCH(O7,YardiSaleName,0))),INDEX([1]!Output_Analysis_Data__2[Year Built],ROW()-2))} -> 1982 | Y7: {=IF($M$1="Manual",IF(AA7<>"",AA7,IF(AB7<>"",AB7,IF(AC7<>"",AC7,""))),INDEX([1]!Output_Analysis_Data__2[Sold Price],ROW()-2))} -> 520000 | Z7: {=IF($M$1="Manual",IFERROR(INDEX(CoStarSaleDate,MATCH(O7,CoStarSaleName,0)),INDEX(YardiSaleDate,MATCH(O7,YardiSaleName,0))),INDEX([1]!Output_Analysis_Data__2[Sale Date],ROW()-2))} -> 45474 | AA7: =IFERROR(INDEX('[1]Agency Loan-Sale Comps'!$J$16:$J$37,MATCH('Comparable Grid'!AD7,'[1]Agency Loan-Sale Comps'!$A$16:$A$37,0),0),"") | AB7: =IFERROR(IF(INDEX(CoStarSalePriceTotal,MATCH(AD7,CoStarSaleCompLookup,0),0)=0,"",INDEX(CoStarSalePriceTotal,MATCH(AD7,CoStarSaleCompLookup,0),0)),"") | AC7: =IFERROR(IF(INDEX(YardiSalePriceTotal,MATCH(AD7,YardiSaleCompLookup,0),0)=0,"",INDEX(YardiSalePriceTotal,MATCH(AD7,YardiSaleCompLookup,0),0)),"") | AD7: =LEFT(Q7,FIND(" ",Q7,1)) -> 209 | AE7: =AE6&IF($L7="x","x","") -> xxx | AG7: New | AH7: 5 | AJ7: Type | AM7: Renovated+ | AN7: 5
C8: Property Name | D8: =rediq_dealname -> Benbrook Apartments | E8: =IFERROR(INDEX($O$3:$O$52,MATCH("x",$AE$3:$AE$52,0),0),"") -> Wind Rush | F8: =IFERROR(INDEX($O$3:$O$52,MATCH("xx",$AE$3:$AE$52,0),0),"") -> Falls & Oak Village, The | G8: =IFERROR(INDEX($O$3:$O$52,MATCH("xxx",$AE$3:$AE$52,0),0),"") -> Range, The | H8: =IFERROR(INDEX($O$3:$O$52,MATCH("xxxx",$AE$3:$AE$52,0),0),"") -> Ridgmar Townhomes | I8: =IFERROR(INDEX($O$3:$O$52,MATCH("xxxxx",$AE$3:$AE$52,0),0),"") -> Sunset Heights | L8: x | M8: =IF($M$1="Manual",IF(Y8="","No Sale Price Disclosed!",""),"") | N8: {=IF($M$1="Manual",IF(AA8<>"","Freddie/Fannie",IF(AB8<>"","CoStar",IF(AC8<>"","Yardi","N/A"))),INDEX([1]!Output_Analysis_Data__2[Info Source],ROW()-2))} -> Yardi | O8: {=IF($M$1="Manual",'[1]Sale Comps'!BY8,INDEX([1]!Output_Analysis_Data__2[Property Name],ROW()-2))} -> Ridgmar Townhomes | P8: =IFERROR(Y8/U8,"") -> 92000 | Q8: {=IF($M$1="Manual",IFERROR(INDEX(CoStarSaleAddress,MATCH(O8,CoStarSaleName,0)),INDEX(YardiSaleAddress,MATCH(O8,YardiSaleName,0))),INDEX([1]!Output_Analysis_Data__2[Property Address],ROW()-2))} -> 2109 Remington Street | R8: {=IF($M$1="Manual",IFERROR(INDEX(CoStarSaleCity,MATCH(O8,CoStarSaleName,0)),INDEX(YardiSaleCity,MATCH(O8,YardiSaleName,0))),INDEX([1]!Output_Analysis_Data__2[City],ROW()-2))} -> Fort Worth | S8: {=IF($M$1="Manual",IFERROR(INDEX(CoStarSaleState,MATCH(O8,CoStarSaleName,0)),INDEX(YardiSaleState,MATCH(O8,YardiSaleName,0))),INDEX([1]!Output_Analysis_Data__2[State],ROW()-2))} -> TX | T8: {=IF($M$1="Manual",IFERROR(INDEX(CoStarSaleZipcodes,MATCH(O8,CoStarSaleName,0)),INDEX(YardiSaleZipcodes,MATCH(O8,YardiSaleName,0))),INDEX([1]!Output_Analysis_Data__2[ZIP],ROW()-2))} -> 76116 | U8: {=IF($M$1="Manual",IFERROR(INDEX(CoStarSaleUnits,MATCH(O8,CoStarSaleName,0)),INDEX(YardiSaleUnits,MATCH(O8,YardiSaleName,0))),INDEX([1]!Output_Analysis_Data__2[Unit Count],ROW()-2))} -> 60 | V8: {=IF($M$1="Manual","",INDEX([1]!Output_Analysis_Data__2[Distance (mi.)],ROW()-2))} -> 2.7010313 | W8: {=IF($M$1="Manual",IFERROR(INDEX(CoStarSaleAvgUnitSize,MATCH(O8,CoStarSaleName,0)),INDEX(YardiSaleAvgUnitSize,MATCH(O8,YardiSaleName,0))),INDEX([1]!Output_Analysis_Data__2[Avg Unit SF],ROW()-2))} -> 1128 | X8: {=IF($M$1="Manual",IFERROR(INDEX(CoStarSaleYearBuilt,MATCH(O8,CoStarSaleName,0)),INDEX(YardiSaleYearBuilt,MATCH(O8,YardiSaleName,0))),INDEX([1]!Output_Analysis_Data__2[Year Built],ROW()-2))} -> 1984 | Y8: {=IF($M$1="Manual",IF(AA8<>"",AA8,IF(AB8<>"",AB8,IF(AC8<>"",AC8,""))),INDEX([1]!Output_Analysis_Data__2[Sold Price],ROW()-2))} -> 5520000 | Z8: {=IF($M$1="Manual",IFERROR(INDEX(CoStarSaleDate,MATCH(O8,CoStarSaleName,0)),INDEX(YardiSaleDate,MATCH(O8,YardiSaleName,0))),INDEX([1]!Output_Analysis_Data__2[Sale Date],ROW()-2))} -> 45688 | AA8: =IFERROR(INDEX('[1]Agency Loan-Sale Comps'!$J$16:$J$37,MATCH('Comparable Grid'!AD8,'[1]Agency Loan-Sale Comps'!$A$16:$A$37,0),0),"") -> 7700000 | AB8: =IFERROR(IF(INDEX(CoStarSalePriceTotal,MATCH(AD8,CoStarSaleCompLookup,0),0)=0,"",INDEX(CoStarSalePriceTotal,MATCH(AD8,CoStarSaleCompLookup,0),0)),"") | AC8: =IFERROR(IF(INDEX(YardiSalePriceTotal,MATCH(AD8,YardiSaleCompLookup,0),0)=0,"",INDEX(YardiSalePriceTotal,MATCH(AD8,YardiSaleCompLookup,0),0)),"") | AD8: =LEFT(Q8,FIND(" ",Q8,1)) -> 2109 | AE8: =AE7&IF($L8="x","x","") -> xxxx | AJ8: Manual | AM8: Premium- | AN8: 6
L9: x | M9: =IF($M$1="Manual",IF(Y9="","No Sale Price Disclosed!",""),"") | N9: {=IF($M$1="Manual",IF(AA9<>"","Freddie/Fannie",IF(AB9<>"","CoStar",IF(AC9<>"","Yardi","N/A"))),INDEX([1]!Output_Analysis_Data__2[Info Source],ROW()-2))} -> Yardi | O9: {=IF($M$1="Manual",'[1]Sale Comps'!BY9,INDEX([1]!Output_Analysis_Data__2[Property Name],ROW()-2))} -> Sunset Heights | P9: =IFERROR(Y9/U9,"") -> 108888.89 | Q9: {=IF($M$1="Manual",IFERROR(INDEX(CoStarSaleAddress,MATCH(O9,CoStarSaleName,0)),INDEX(YardiSaleAddress,MATCH(O9,YardiSaleName,0))),INDEX([1]!Output_Analysis_Data__2[Property Address],ROW()-2))} -> 4727 Wellesley Avenue | R9: {=IF($M$1="Manual",IFERROR(INDEX(CoStarSaleCity,MATCH(O9,CoStarSaleName,0)),INDEX(YardiSaleCity,MATCH(O9,YardiSaleName,0))),INDEX([1]!Output_Analysis_Data__2[City],ROW()-2))} -> Fort Worth | S9: {=IF($M$1="Manual",IFERROR(INDEX(CoStarSaleState,MATCH(O9,CoStarSaleName,0)),INDEX(YardiSaleState,MATCH(O9,YardiSaleName,0))),INDEX([1]!Output_Analysis_Data__2[State],ROW()-2))} -> TX | T9: {=IF($M$1="Manual",IFERROR(INDEX(CoStarSaleZipcodes,MATCH(O9,CoStarSaleName,0)),INDEX(YardiSaleZipcodes,MATCH(O9,YardiSaleName,0))),INDEX([1]!Output_Analysis_Data__2[ZIP],ROW()-2))} -> 76107 | U9: {=IF($M$1="Manual",IFERROR(INDEX(CoStarSaleUnits,MATCH(O9,CoStarSaleName,0)),INDEX(YardiSaleUnits,MATCH(O9,YardiSaleName,0))),INDEX([1]!Output_Analysis_Data__2[Unit Count],ROW()-2))} -> 90 | V9: {=IF($M$1="Manual","",INDEX([1]!Output_Analysis_Data__2[Distance (mi.)],ROW()-2))} -> 3.8014118 | W9: {=IF($M$1="Manual",IFERROR(INDEX(CoStarSaleAvgUnitSize,MATCH(O9,CoStarSaleName,0)),INDEX(YardiSaleAvgUnitSize,MATCH(O9,YardiSaleName,0))),INDEX([1]!Output_Analysis_Data__2[Avg Unit SF],ROW()-2))} -> 818 | X9: {=IF($M$1="Manual",IFERROR(INDEX(CoStarSaleYearBuilt,MATCH(O9,CoStarSaleName,0)),INDEX(YardiSaleYearBuilt,MATCH(O9,YardiSaleName,0))),INDEX([1]!Output_Analysis_Data__2[Year Built],ROW()-2))} -> 1970 | Y9: {=IF($M$1="Manual",IF(AA9<>"",AA9,IF(AB9<>"",AB9,IF(AC9<>"",AC9,""))),INDEX([1]!Output_Analysis_Data__2[Sold Price],ROW()-2))} -> 9800000 | Z9: {=IF($M$1="Manual",IFERROR(INDEX(CoStarSaleDate,MATCH(O9,CoStarSaleName,0)),INDEX(YardiSaleDate,MATCH(O9,YardiSaleName,0))),INDEX([1]!Output_Analysis_Data__2[Sale Date],ROW()-2))} -> 45379 | AA9: =IFERROR(INDEX('[1]Agency Loan-Sale Comps'!$J$16:$J$37,MATCH('Comparable Grid'!AD9,'[1]Agency Loan-Sale Comps'!$A$16:$A$37,0),0),"") | AB9: =IFERROR(IF(INDEX(CoStarSalePriceTotal,MATCH(AD9,CoStarSaleCompLookup,0),0)=0,"",INDEX(CoStarSalePriceTotal,MATCH(AD9,CoStarSaleCompLookup,0),0)),"") | AC9: =IFERROR(IF(INDEX(YardiSalePriceTotal,MATCH(AD9,YardiSaleCompLookup,0),0)=0,"",INDEX(YardiSalePriceTotal,MATCH(AD9,YardiSaleCompLookup,0),0)),"") | AD9: =LEFT(Q9,FIND(" ",Q9,1)) -> 4727 | AE9: =AE8&IF($L9="x","x","") -> xxxxx | AJ9: Automatic | AM9: Premium | AN9: 7
C10: Address | D10: =rediq_address1 -> 4639 Williams Rd | E10: =IFERROR(INDEX($Q$3:$Q$52,MATCH("x",$AE$3:$AE$52,0),0),"") -> 3500 Renzel Blvd | F10: =IFERROR(INDEX($Q$3:$Q$52,MATCH("xx",$AE$3:$AE$52,0),0),"") -> 9001 South Normandale Street | G10: =IFERROR(INDEX($Q$3:$Q$52,MATCH("xxx",$AE$3:$AE$52,0),0),"") -> 2925 West Normandale Street | H10: =IFERROR(INDEX($Q$3:$Q$52,MATCH("xxxx",$AE$3:$AE$52,0),0),"") -> 2109 Remington Street | I10: =IFERROR(INDEX($Q$3:$Q$52,MATCH("xxxxx",$AE$3:$AE$52,0),0),"") -> 4727 Wellesley Avenue | M10: =IF($M$1="Manual",IF(Y10="","No Sale Price Disclosed!",""),"") | N10: {=IF($M$1="Manual",IF(AA10<>"","Freddie/Fannie",IF(AB10<>"","CoStar",IF(AC10<>"","Yardi","N/A"))),INDEX([1]!Output_Analysis_Data__2[Info Source],ROW()-2))} -> Yardi | O10: {=IF($M$1="Manual",'[1]Sale Comps'!BY10,INDEX([1]!Output_Analysis_Data__2[Property Name],ROW()-2))} -> Candle Chase | P10: =IFERROR(Y10/U10,"") -> 180431.03 | Q10: {=IF($M$1="Manual",IFERROR(INDEX(CoStarSaleAddress,MATCH(O10,CoStarSaleName,0)),INDEX(YardiSaleAddress,MATCH(O10,YardiSaleName,0))),INDEX([1]!Output_Analysis_Data__2[Property Address],ROW()-2))} -> 6822 South Hulen Street | R10: {=IF($M$1="Manual",IFERROR(INDEX(CoStarSaleCity,MATCH(O10,CoStarSaleName,0)),INDEX(YardiSaleCity,MATCH(O10,YardiSaleName,0))),INDEX([1]!Output_Analysis_Data__2[City],ROW()-2))} -> Fort Worth | S10: {=IF($M$1="Manual",IFERROR(INDEX(CoStarSaleState,MATCH(O10,CoStarSaleName,0)),INDEX(YardiSaleState,MATCH(O10,YardiSaleName,0))),INDEX([1]!Output_Analysis_Data__2[State],ROW()-2))} -> TX | T10: {=IF($M$1="Manual",IFERROR(INDEX(CoStarSaleZipcodes,MATCH(O10,CoStarSaleName,0)),INDEX(YardiSaleZipcodes,MATCH(O10,YardiSaleName,0))),INDEX([1]!Output_Analysis_Data__2[ZIP],ROW()-2))} -> 76133 | U10: {=IF($M$1="Manual",IFERROR(INDEX(CoStarSaleUnits,MATCH(O10,CoStarSaleName,0)),INDEX(YardiSaleUnits,MATCH(O10,YardiSaleName,0))),INDEX([1]!Output_Analysis_Data__2[Unit Count],ROW()-2))} -> 116 | V10: {=IF($M$1="Manual","",INDEX([1]!Output_Analysis_Data__2[Distance (mi.)],ROW()-2))} -> 5.1561736 | W10: {=IF($M$1="Manual",IFERROR(INDEX(CoStarSaleAvgUnitSize,MATCH(O10,CoStarSaleName,0)),INDEX(YardiSaleAvgUnitSize,MATCH(O10,YardiSaleName,0))),INDEX([1]!Output_Analysis_Data__2[Avg Unit SF],ROW()-2))} -> 952 | X10: {=IF($M$1="Manual",IFERROR(INDEX(CoStarSaleYearBuilt,MATCH(O10,CoStarSaleName,0)),INDEX(YardiSaleYearBuilt,MATCH(O10,YardiSaleName,0))),INDEX([1]!Output_Analysis_Data__2[Year Built],ROW()-2))} -> 1969 | Y10: {=IF($M$1="Manual",IF(AA10<>"",AA10,IF(AB10<>"",AB10,IF(AC10<>"",AC10,""))),INDEX([1]!Output_Analysis_Data__2[Sold Price],ROW()-2))} -> 20930000 | Z10: {=IF($M$1="Manual",IFERROR(INDEX(CoStarSaleDate,MATCH(O10,CoStarSaleName,0)),INDEX(YardiSaleDate,MATCH(O10,YardiSaleName,0))),INDEX([1]!Output_Analysis_Data__2[Sale Date],ROW()-2))} -> 45743 | AA10: =IFERROR(INDEX('[1]Agency Loan-Sale Comps'!$J$16:$J$37,MATCH('Comparable Grid'!AD10,'[1]Agency Loan-Sale Comps'!$A$16:$A$37,0),0),"") | AB10: =IFERROR(IF(INDEX(CoStarSalePriceTotal,MATCH(AD10,CoStarSaleCompLookup,0),0)=0,"",INDEX(CoStarSalePriceTotal,MATCH(AD10,CoStarSaleCompLookup,0),0)),"") | AC10: =IFERROR(IF(INDEX(YardiSalePriceTotal,MATCH(AD10,YardiSaleCompLookup,0),0)=0,"",INDEX(YardiSalePriceTotal,MATCH(AD10,YardiSaleCompLookup,0),0)),"") | AD10: =LEFT(Q10,FIND(" ",Q10,1)) -> 6822 | AE10: =AE9&IF($L10="x","x","") -> xxxxx | AM10: Premium+ | AN10: 8
C11: City | D11: =rediq_city -> Benbrook | E11: =IFERROR(INDEX($R$3:$R$52,MATCH("x",$AE$3:$AE$52,0),0),"") -> Fort Worth | F11: =IFERROR(INDEX($R$3:$R$52,MATCH("xx",$AE$3:$AE$52,0),0),"") -> Fort Worth | G11: =IFERROR(INDEX($R$3:$R$52,MATCH("xxx",$AE$3:$AE$52,0),0),"") -> Fort Worth | H11: =IFERROR(INDEX($R$3:$R$52,MATCH("xxxx",$AE$3:$AE$52,0),0),"") -> Fort Worth | I11: =IFERROR(INDEX($R$3:$R$52,MATCH("xxxxx",$AE$3:$AE$52,0),0),"") -> Fort Worth | M11: =IF($M$1="Manual",IF(Y11="","No Sale Price Disclosed!",""),"") | N11: {=IF($M$1="Manual",IF(AA11<>"","Freddie/Fannie",IF(AB11<>"","CoStar",IF(AC11<>"","Yardi","N/A"))),INDEX([1]!Output_Analysis_Data__2[Info Source],ROW()-2))} -> Yardi | O11: {=IF($M$1="Manual",'[1]Sale Comps'!BY11,INDEX([1]!Output_Analysis_Data__2[Property Name],ROW()-2))} -> Dakota | P11: =IFERROR(Y11/U11,"") -> 87500 | Q11: {=IF($M$1="Manual",IFERROR(INDEX(CoStarSaleAddress,MATCH(O11,CoStarSaleName,0)),INDEX(YardiSaleAddress,MATCH(O11,YardiSaleName,0))),INDEX([1]!Output_Analysis_Data__2[Property Address],ROW()-2))} -> 6218 Finbro Drive | R11: {=IF($M$1="Manual",IFERROR(INDEX(CoStarSaleCity,MATCH(O11,CoStarSaleName,0)),INDEX(YardiSaleCity,MATCH(O11,YardiSaleName,0))),INDEX([1]!Output_Analysis_Data__2[City],ROW()-2))} -> Fort Worth | S11: {=IF($M$1="Manual",IFERROR(INDEX(CoStarSaleState,MATCH(O11,CoStarSaleName,0)),INDEX(YardiSaleState,MATCH(O11,YardiSaleName,0))),INDEX([1]!Output_Analysis_Data__2[State],ROW()-2))} -> TX | T11: {=IF($M$1="Manual",IFERROR(INDEX(CoStarSaleZipcodes,MATCH(O11,CoStarSaleName,0)),INDEX(YardiSaleZipcodes,MATCH(O11,YardiSaleName,0))),INDEX([1]!Output_Analysis_Data__2[ZIP],ROW()-2))} -> 76133 | U11: {=IF($M$1="Manual",IFERROR(INDEX(CoStarSaleUnits,MATCH(O11,CoStarSaleName,0)),INDEX(YardiSaleUnits,MATCH(O11,YardiSaleName,0))),INDEX([1]!Output_Analysis_Data__2[Unit Count],ROW()-2))} -> 120 | V11: {=IF($M$1="Manual","",INDEX([1]!Output_Analysis_Data__2[Distance (mi.)],ROW()-2))} -> 6.3024208 | W11: {=IF($M$1="Manual",IFERROR(INDEX(CoStarSaleAvgUnitSize,MATCH(O11,CoStarSaleName,0)),INDEX(YardiSaleAvgUnitSize,MATCH(O11,YardiSaleName,0))),INDEX([1]!Output_Analysis_Data__2[Avg Unit SF],ROW()-2))} -> 785 | X11: {=IF($M$1="Manual",IFERROR(INDEX(CoStarSaleYearBuilt,MATCH(O11,CoStarSaleName,0)),INDEX(YardiSaleYearBuilt,MATCH(O11,YardiSaleName,0))),INDEX([1]!Output_Analysis_Data__2[Year Built],ROW()-2))} -> 1980 | Y11: {=IF($M$1="Manual",IF(AA11<>"",AA11,IF(AB11<>"",AB11,IF(AC11<>"",AC11,""))),INDEX([1]!Output_Analysis_Data__2[Sold Price],ROW()-2))} -> 10500000 | Z11: {=IF($M$1="Manual",IFERROR(INDEX(CoStarSaleDate,MATCH(O11,CoStarSaleName,0)),INDEX(YardiSaleDate,MATCH(O11,YardiSaleName,0))),INDEX([1]!Output_Analysis_Data__2[Sale Date],ROW()-2))} -> 45289 | AA11: =IFERROR(INDEX('[1]Agency Loan-Sale Comps'!$J$16:$J$37,MATCH('Comparable Grid'!AD11,'[1]Agency Loan-Sale Comps'!$A$16:$A$37,0),0),"") | AB11: =IFERROR(IF(INDEX(CoStarSalePriceTotal,MATCH(AD11,CoStarSaleCompLookup,0),0)=0,"",INDEX(CoStarSalePriceTotal,MATCH(AD11,CoStarSaleCompLookup,0),0)),"") | AC11: =IFERROR(IF(INDEX(YardiSalePriceTotal,MATCH(AD11,YardiSaleCompLookup,0),0)=0,"",INDEX(YardiSalePriceTotal,MATCH(AD11,YardiSaleCompLookup,0),0)),"") | AD11: =LEFT(Q11,FIND(" ",Q11,1)) -> 6218 | AE11: =AE10&IF($L11="x","x","") -> xxxxx
C12: State | D12: =rediq_state -> TX | E12: =IFERROR(INDEX($S$3:$S$52,MATCH("x",$AE$3:$AE$52,0),0),"") -> TX | F12: =IFERROR(INDEX($S$3:$S$52,MATCH("xx",$AE$3:$AE$52,0),0),"") -> TX | G12: =IFERROR(INDEX($S$3:$S$52,MATCH("xxx",$AE$3:$AE$52,0),0),"") -> TX | H12: =IFERROR(INDEX($S$3:$S$52,MATCH("xxxx",$AE$3:$AE$52,0),0),"") -> TX | I12: =IFERROR(INDEX($S$3:$S$52,MATCH("xxxxx",$AE$3:$AE$52,0),0),"") -> TX | L12: x | M12: =IF($M$1="Manual",IF(Y12="","No Sale Price Disclosed!",""),"") | N12: {=IF($M$1="Manual",IF(AA12<>"","Freddie/Fannie",IF(AB12<>"","CoStar",IF(AC12<>"","Yardi","N/A"))),INDEX([1]!Output_Analysis_Data__2[Info Source],ROW()-2))} -> TMG Broker | O12: {=IF($M$1="Manual",'[1]Sale Comps'!BY12,INDEX([1]!Output_Analysis_Data__2[Property Name],ROW()-2))} -> Vista Del Sol | P12: =IFERROR(Y12/U12,"") -> 98611.111 | Q12: {=IF($M$1="Manual",IFERROR(INDEX(CoStarSaleAddress,MATCH(O12,CoStarSaleName,0)),INDEX(YardiSaleAddress,MATCH(O12,YardiSaleName,0))),INDEX([1]!Output_Analysis_Data__2[Property Address],ROW()-2))} -> 4316 Baldwin Avenue | R12: {=IF($M$1="Manual",IFERROR(INDEX(CoStarSaleCity,MATCH(O12,CoStarSaleName,0)),INDEX(YardiSaleCity,MATCH(O12,YardiSaleName,0))),INDEX([1]!Output_Analysis_Data__2[City],ROW()-2))} -> Fort Worth | S12: {=IF($M$1="Manual",IFERROR(INDEX(CoStarSaleState,MATCH(O12,CoStarSaleName,0)),INDEX(YardiSaleState,MATCH(O12,YardiSaleName,0))),INDEX([1]!Output_Analysis_Data__2[State],ROW()-2))} -> TX | T12: {=IF($M$1="Manual",IFERROR(INDEX(CoStarSaleZipcodes,MATCH(O12,CoStarSaleName,0)),INDEX(YardiSaleZipcodes,MATCH(O12,YardiSaleName,0))),INDEX([1]!Output_Analysis_Data__2[ZIP],ROW()-2))} -> 76115 | U12: {=IF($M$1="Manual",IFERROR(INDEX(CoStarSaleUnits,MATCH(O12,CoStarSaleName,0)),INDEX(YardiSaleUnits,MATCH(O12,YardiSaleName,0))),INDEX([1]!Output_Analysis_Data__2[Unit Count],ROW()-2))} -> 54 | V12: {=IF($M$1="Manual","",INDEX([1]!Output_Analysis_Data__2[Distance (mi.)],ROW()-2))} -> 6.7539166 | W12: {=IF($M$1="Manual",IFERROR(INDEX(CoStarSaleAvgUnitSize,MATCH(O12,CoStarSaleName,0)),INDEX(YardiSaleAvgUnitSize,MATCH(O12,YardiSaleName,0))),INDEX([1]!Output_Analysis_Data__2[Avg Unit SF],ROW()-2))} -> 597 | X12: {=IF($M$1="Manual",IFERROR(INDEX(CoStarSaleYearBuilt,MATCH(O12,CoStarSaleName,0)),INDEX(YardiSaleYearBuilt,MATCH(O12,YardiSaleName,0))),INDEX([1]!Output_Analysis_Data__2[Year Built],ROW()-2))} -> 1968 | Y12: {=IF($M$1="Manual",IF(AA12<>"",AA12,IF(AB12<>"",AB12,IF(AC12<>"",AC12,""))),INDEX([1]!Output_Analysis_Data__2[Sold Price],ROW()-2))} -> 5325000 | Z12: {=IF($M$1="Manual",IFERROR(INDEX(CoStarSaleDate,MATCH(O12,CoStarSaleName,0)),INDEX(YardiSaleDate,MATCH(O12,YardiSaleName,0))),INDEX([1]!Output_Analysis_Data__2[Sale Date],ROW()-2))} -> 45931 | AA12: =IFERROR(INDEX('[1]Agency Loan-Sale Comps'!$J$16:$J$37,MATCH('Comparable Grid'!AD12,'[1]Agency Loan-Sale Comps'!$A$16:$A$37,0),0),"") | AB12: =IFERROR(IF(INDEX(CoStarSalePriceTotal,MATCH(AD12,CoStarSaleCompLookup,0),0)=0,"",INDEX(CoStarSalePriceTotal,MATCH(AD12,CoStarSaleCompLookup,0),0)),"") | AC12: =IFERROR(IF(INDEX(YardiSalePriceTotal,MATCH(AD12,YardiSaleCompLookup,0),0)=0,"",INDEX(YardiSalePriceTotal,MATCH(AD12,YardiSaleCompLookup,0),0)),"") | AD12: =LEFT(Q12,FIND(" ",Q12,1)) -> 4316 | AE12: =AE11&IF($L12="x","x","") -> xxxxxx
C13: Zip | D13: =rediq_zip -> 76116 | E13: =IFERROR(INDEX($T$3:$T$52,MATCH("x",$AE$3:$AE$52,0),0),"") -> 76116 | F13: =IFERROR(INDEX($T$3:$T$52,MATCH("xx",$AE$3:$AE$52,0),0),"") -> 76116 | G13: =IFERROR(INDEX($T$3:$T$52,MATCH("xxx",$AE$3:$AE$52,0),0),"") -> 76116 | H13: =IFERROR(INDEX($T$3:$T$52,MATCH("xxxx",$AE$3:$AE$52,0),0),"") -> 76116 | I13: =IFERROR(INDEX($T$3:$T$52,MATCH("xxxxx",$AE$3:$AE$52,0),0),"") -> 76107 | M13: =IF($M$1="Manual",IF(Y13="","No Sale Price Disclosed!",""),"") | N13: {=IF($M$1="Manual",IF(AA13<>"","Freddie/Fannie",IF(AB13<>"","CoStar",IF(AC13<>"","Yardi","N/A"))),INDEX([1]!Output_Analysis_Data__2[Info Source],ROW()-2))} -> Fannie | O13: {=IF($M$1="Manual",'[1]Sale Comps'!BY13,INDEX([1]!Output_Analysis_Data__2[Property Name],ROW()-2))} -> Morningside | P13: =IFERROR(Y13/U13,"") -> 92338.71 | Q13: {=IF($M$1="Manual",IFERROR(INDEX(CoStarSaleAddress,MATCH(O13,CoStarSaleName,0)),INDEX(YardiSaleAddress,MATCH(O13,YardiSaleName,0))),INDEX([1]!Output_Analysis_Data__2[Property Address],ROW()-2))} -> 2900 South Fwy | R13: {=IF($M$1="Manual",IFERROR(INDEX(CoStarSaleCity,MATCH(O13,CoStarSaleName,0)),INDEX(YardiSaleCity,MATCH(O13,YardiSaleName,0))),INDEX([1]!Output_Analysis_Data__2[City],ROW()-2))} -> Fort Worth | S13: {=IF($M$1="Manual",IFERROR(INDEX(CoStarSaleState,MATCH(O13,CoStarSaleName,0)),INDEX(YardiSaleState,MATCH(O13,YardiSaleName,0))),INDEX([1]!Output_Analysis_Data__2[State],ROW()-2))} -> TX | T13: {=IF($M$1="Manual",IFERROR(INDEX(CoStarSaleZipcodes,MATCH(O13,CoStarSaleName,0)),INDEX(YardiSaleZipcodes,MATCH(O13,YardiSaleName,0))),INDEX([1]!Output_Analysis_Data__2[ZIP],ROW()-2))} -> 76104 | U13: {=IF($M$1="Manual",IFERROR(INDEX(CoStarSaleUnits,MATCH(O13,CoStarSaleName,0)),INDEX(YardiSaleUnits,MATCH(O13,YardiSaleName,0))),INDEX([1]!Output_Analysis_Data__2[Unit Count],ROW()-2))} -> 124 | V13: {=IF($M$1="Manual","",INDEX([1]!Output_Analysis_Data__2[Distance (mi.)],ROW()-2))} -> 7.5865999 | W13: {=IF($M$1="Manual",IFERROR(INDEX(CoStarSaleAvgUnitSize,MATCH(O13,CoStarSaleName,0)),INDEX(YardiSaleAvgUnitSize,MATCH(O13,YardiSaleName,0))),INDEX([1]!Output_Analysis_Data__2[Avg Unit SF],ROW()-2))} -> 685 | X13: {=IF($M$1="Manual",IFERROR(INDEX(CoStarSaleYearBuilt,MATCH(O13,CoStarSaleName,0)),INDEX(YardiSaleYearBuilt,MATCH(O13,YardiSaleName,0))),INDEX([1]!Output_Analysis_Data__2[Year Built],ROW()-2))} -> 1968 | Y13: {=IF($M$1="Manual",IF(AA13<>"",AA13,IF(AB13<>"",AB13,IF(AC13<>"",AC13,""))),INDEX([1]!Output_Analysis_Data__2[Sold Price],ROW()-2))} -> 11450000 | Z13: {=IF($M$1="Manual",IFERROR(INDEX(CoStarSaleDate,MATCH(O13,CoStarSaleName,0)),INDEX(YardiSaleDate,MATCH(O13,YardiSaleName,0))),INDEX([1]!Output_Analysis_Data__2[Sale Date],ROW()-2))} -> 45163 | AA13: =IFERROR(INDEX('[1]Agency Loan-Sale Comps'!$J$16:$J$37,MATCH('Comparable Grid'!AD13,'[1]Agency Loan-Sale Comps'!$A$16:$A$37,0),0),"") | AB13: =IFERROR(IF(INDEX(CoStarSalePriceTotal,MATCH(AD13,CoStarSaleCompLookup,0),0)=0,"",INDEX(CoStarSalePriceTotal,MATCH(AD13,CoStarSaleCompLookup,0),0)),"") | AC13: =IFERROR(IF(INDEX(YardiSalePriceTotal,MATCH(AD13,YardiSaleCompLookup,0),0)=0,"",INDEX(YardiSalePriceTotal,MATCH(AD13,YardiSaleCompLookup,0),0)),"") | AD13: =LEFT(Q13,FIND(" ",Q13,1)) -> 2900 | AE13: =AE12&IF($L13="x","x","") -> xxxxxx
C14: Primary Data Source | E14: =IFERROR(INDEX($N$3:$N$52,MATCH("x",$AE$3:$AE$52,0),0),"") -> Yardi | F14: =IFERROR(INDEX($N$3:$N$52,MATCH("xx",$AE$3:$AE$52,0),0),"") -> Yardi | G14: =IFERROR(INDEX($N$3:$N$52,MATCH("xxx",$AE$3:$AE$52,0),0),"") -> Fannie | H14: =IFERROR(INDEX($N$3:$N$52,MATCH("xxxx",$AE$3:$AE$52,0),0),"") -> Yardi | I14: =IFERROR(INDEX($N$3:$N$52,MATCH("xxxxx",$AE$3:$AE$52,0),0),"") -> Yardi | M14: =IF($M$1="Manual",IF(Y14="","No Sale Price Disclosed!",""),"") | N14: {=IF($M$1="Manual",IF(AA14<>"","Freddie/Fannie",IF(AB14<>"","CoStar",IF(AC14<>"","Yardi","N/A"))),INDEX([1]!Output_Analysis_Data__2[Info Source],ROW()-2))} -> Yardi | O14: {=IF($M$1="Manual",'[1]Sale Comps'!BY14,INDEX([1]!Output_Analysis_Data__2[Property Name],ROW()-2))} -> Hampton Townhomes | P14: =IFERROR(Y14/U14,"") -> 140000 | Q14: {=IF($M$1="Manual",IFERROR(INDEX(CoStarSaleAddress,MATCH(O14,CoStarSaleName,0)),INDEX(YardiSaleAddress,MATCH(O14,YardiSaleName,0))),INDEX([1]!Output_Analysis_Data__2[Property Address],ROW()-2))} -> 121 South Hampton Road | R14: {=IF($M$1="Manual",IFERROR(INDEX(CoStarSaleCity,MATCH(O14,CoStarSaleName,0)),INDEX(YardiSaleCity,MATCH(O14,YardiSaleName,0))),INDEX([1]!Output_Analysis_Data__2[City],ROW()-2))} -> Crowley | S14: {=IF($M$1="Manual",IFERROR(INDEX(CoStarSaleState,MATCH(O14,CoStarSaleName,0)),INDEX(YardiSaleState,MATCH(O14,YardiSaleName,0))),INDEX([1]!Output_Analysis_Data__2[State],ROW()-2))} -> TX | T14: {=IF($M$1="Manual",IFERROR(INDEX(CoStarSaleZipcodes,MATCH(O14,CoStarSaleName,0)),INDEX(YardiSaleZipcodes,MATCH(O14,YardiSaleName,0))),INDEX([1]!Output_Analysis_Data__2[ZIP],ROW()-2))} -> 76036 | U14: {=IF($M$1="Manual",IFERROR(INDEX(CoStarSaleUnits,MATCH(O14,CoStarSaleName,0)),INDEX(YardiSaleUnits,MATCH(O14,YardiSaleName,0))),INDEX([1]!Output_Analysis_Data__2[Unit Count],ROW()-2))} -> 76 | V14: {=IF($M$1="Manual","",INDEX([1]!Output_Analysis_Data__2[Distance (mi.)],ROW()-2))} -> 10.393325 | W14: {=IF($M$1="Manual",IFERROR(INDEX(CoStarSaleAvgUnitSize,MATCH(O14,CoStarSaleName,0)),INDEX(YardiSaleAvgUnitSize,MATCH(O14,YardiSaleName,0))),INDEX([1]!Output_Analysis_Data__2[Avg Unit SF],ROW()-2))} -> 973 | X14: {=IF($M$1="Manual",IFERROR(INDEX(CoStarSaleYearBuilt,MATCH(O14,CoStarSaleName,0)),INDEX(YardiSaleYearBuilt,MATCH(O14,YardiSaleName,0))),INDEX([1]!Output_Analysis_Data__2[Year Built],ROW()-2))} -> 1983 | Y14: {=IF($M$1="Manual",IF(AA14<>"",AA14,IF(AB14<>"",AB14,IF(AC14<>"",AC14,""))),INDEX([1]!Output_Analysis_Data__2[Sold Price],ROW()-2))} -> 10640000 | Z14: {=IF($M$1="Manual",IFERROR(INDEX(CoStarSaleDate,MATCH(O14,CoStarSaleName,0)),INDEX(YardiSaleDate,MATCH(O14,YardiSaleName,0))),INDEX([1]!Output_Analysis_Data__2[Sale Date],ROW()-2))} -> 45657 | AA14: =IFERROR(INDEX('[1]Agency Loan-Sale Comps'!$J$16:$J$37,MATCH('Comparable Grid'!AD14,'[1]Agency Loan-Sale Comps'!$A$16:$A$37,0),0),"") | AB14: =IFERROR(IF(INDEX(CoStarSalePriceTotal,MATCH(AD14,CoStarSaleCompLookup,0),0)=0,"",INDEX(CoStarSalePriceTotal,MATCH(AD14,CoStarSaleCompLookup,0),0)),"") | AC14: =IFERROR(IF(INDEX(YardiSalePriceTotal,MATCH(AD14,YardiSaleCompLookup,0),0)=0,"",INDEX(YardiSalePriceTotal,MATCH(AD14,YardiSaleCompLookup,0),0)),"") | AD14: =LEFT(Q14,FIND(" ",Q14,1)) -> 121 | AE14: =AE13&IF($L14="x","x","") -> xxxxxx
C15: ="Sale Price" -> Sale Price | E15: =IFERROR(INDEX($Y$3:$Y$52,MATCH("x",$AE$3:$AE$52,0),0),"") -> 31000000 | F15: =IFERROR(INDEX($Y$3:$Y$52,MATCH("xx",$AE$3:$AE$52,0),0),"") -> 41580000 | G15: =IFERROR(INDEX($Y$3:$Y$52,MATCH("xxx",$AE$3:$AE$52,0),0),"") -> 20300000 | H15: =IFERROR(INDEX($Y$3:$Y$52,MATCH("xxxx",$AE$3:$AE$52,0),0),"") -> 5520000 | I15: =IFERROR(INDEX($Y$3:$Y$52,MATCH("xxxxx",$AE$3:$AE$52,0),0),"") -> 9800000 | M15: =IF($M$1="Manual",IF(Y15="","No Sale Price Disclosed!",""),"") | N15: {=IF($M$1="Manual",IF(AA15<>"","Freddie/Fannie",IF(AB15<>"","CoStar",IF(AC15<>"","Yardi","N/A"))),INDEX([1]!Output_Analysis_Data__2[Info Source],ROW()-2))} -> Yardi | O15: {=IF($M$1="Manual",'[1]Sale Comps'!BY15,INDEX([1]!Output_Analysis_Data__2[Property Name],ROW()-2))} -> Northwood | P15: =IFERROR(Y15/U15,"") -> 109900 | Q15: {=IF($M$1="Manual",IFERROR(INDEX(CoStarSaleAddress,MATCH(O15,CoStarSaleName,0)),INDEX(YardiSaleAddress,MATCH(O15,YardiSaleName,0))),INDEX([1]!Output_Analysis_Data__2[Property Address],ROW()-2))} -> 4301 Weber Street | R15: {=IF($M$1="Manual",IFERROR(INDEX(CoStarSaleCity,MATCH(O15,CoStarSaleName,0)),INDEX(YardiSaleCity,MATCH(O15,YardiSaleName,0))),INDEX([1]!Output_Analysis_Data__2[City],ROW()-2))} -> Fort Worth | S15: {=IF($M$1="Manual",IFERROR(INDEX(CoStarSaleState,MATCH(O15,CoStarSaleName,0)),INDEX(YardiSaleState,MATCH(O15,YardiSaleName,0))),INDEX([1]!Output_Analysis_Data__2[State],ROW()-2))} -> TX | T15: {=IF($M$1="Manual",IFERROR(INDEX(CoStarSaleZipcodes,MATCH(O15,CoStarSaleName,0)),INDEX(YardiSaleZipcodes,MATCH(O15,YardiSaleName,0))),INDEX([1]!Output_Analysis_Data__2[ZIP],ROW()-2))} -> 76106 | U15: {=IF($M$1="Manual",IFERROR(INDEX(CoStarSaleUnits,MATCH(O15,CoStarSaleName,0)),INDEX(YardiSaleUnits,MATCH(O15,YardiSaleName,0))),INDEX([1]!Output_Analysis_Data__2[Unit Count],ROW()-2))} -> 100 | V15: {=IF($M$1="Manual","",INDEX([1]!Output_Analysis_Data__2[Distance (mi.)],ROW()-2))} -> 10.462589 | W15: {=IF($M$1="Manual",IFERROR(INDEX(CoStarSaleAvgUnitSize,MATCH(O15,CoStarSaleName,0)),INDEX(YardiSaleAvgUnitSize,MATCH(O15,YardiSaleName,0))),INDEX([1]!Output_Analysis_Data__2[Avg Unit SF],ROW()-2))} -> 888 | X15: {=IF($M$1="Manual",IFERROR(INDEX(CoStarSaleYearBuilt,MATCH(O15,CoStarSaleName,0)),INDEX(YardiSaleYearBuilt,MATCH(O15,YardiSaleName,0))),INDEX([1]!Output_Analysis_Data__2[Year Built],ROW()-2))} -> 1972 | Y15: {=IF($M$1="Manual",IF(AA15<>"",AA15,IF(AB15<>"",AB15,IF(AC15<>"",AC15,""))),INDEX([1]!Output_Analysis_Data__2[Sold Price],ROW()-2))} -> 10990000 | Z15: {=IF($M$1="Manual",IFERROR(INDEX(CoStarSaleDate,MATCH(O15,CoStarSaleName,0)),INDEX(YardiSaleDate,MATCH(O15,YardiSaleName,0))),INDEX([1]!Output_Analysis_Data__2[Sale Date],ROW()-2))} -> 45289 | AA15: =IFERROR(INDEX('[1]Agency Loan-Sale Comps'!$J$16:$J$37,MATCH('Comparable Grid'!AD15,'[1]Agency Loan-Sale Comps'!$A$16:$A$37,0),0),"") | AB15: =IFERROR(IF(INDEX(CoStarSalePriceTotal,MATCH(AD15,CoStarSaleCompLookup,0),0)=0,"",INDEX(CoStarSalePriceTotal,MATCH(AD15,CoStarSaleCompLookup,0),0)),"") | AC15: =IFERROR(IF(INDEX(YardiSalePriceTotal,MATCH(AD15,YardiSaleCompLookup,0),0)=0,"",INDEX(YardiSalePriceTotal,MATCH(AD15,YardiSaleCompLookup,0),0)),"") | AD15: =LEFT(Q15,FIND(" ",Q15,1)) -> 4301 | AE15: =AE14&IF($L15="x","x","") -> xxxxxx
C16: Sale Date | E16: =IFERROR(INDEX($Z$3:$Z$52,MATCH("x",$AE$3:$AE$52,0),0),"") -> 45849 | F16: =IFERROR(INDEX($Z$3:$Z$52,MATCH("xx",$AE$3:$AE$52,0),0),"") -> 45702 | G16: =IFERROR(INDEX($Z$3:$Z$52,MATCH("xxx",$AE$3:$AE$52,0),0),"") -> 45183 | H16: =IFERROR(INDEX($Z$3:$Z$52,MATCH("xxxx",$AE$3:$AE$52,0),0),"") -> 45688 | I16: =IFERROR(INDEX($Z$3:$Z$52,MATCH("xxxxx",$AE$3:$AE$52,0),0),"") -> 45379 | M16: =IF($M$1="Manual",IF(Y16="","No Sale Price Disclosed!",""),"") | N16: {=IF($M$1="Manual",IF(AA16<>"","Freddie/Fannie",IF(AB16<>"","CoStar",IF(AC16<>"","Yardi","N/A"))),INDEX([1]!Output_Analysis_Data__2[Info Source],ROW()-2))} -> Yardi | O16: {=IF($M$1="Manual",'[1]Sale Comps'!BY16,INDEX([1]!Output_Analysis_Data__2[Property Name],ROW()-2))} -> Woods of Haltom | P16: =IFERROR(Y16/U16,"") -> 120340.91 | Q16: {=IF($M$1="Manual",IFERROR(INDEX(CoStarSaleAddress,MATCH(O16,CoStarSaleName,0)),INDEX(YardiSaleAddress,MATCH(O16,YardiSaleName,0))),INDEX([1]!Output_Analysis_Data__2[Property Address],ROW()-2))} -> 4812 Waldemar Street | R16: {=IF($M$1="Manual",IFERROR(INDEX(CoStarSaleCity,MATCH(O16,CoStarSaleName,0)),INDEX(YardiSaleCity,MATCH(O16,YardiSaleName,0))),INDEX([1]!Output_Analysis_Data__2[City],ROW()-2))} -> Haltom City | S16: {=IF($M$1="Manual",IFERROR(INDEX(CoStarSaleState,MATCH(O16,CoStarSaleName,0)),INDEX(YardiSaleState,MATCH(O16,YardiSaleName,0))),INDEX([1]!Output_Analysis_Data__2[State],ROW()-2))} -> TX | T16: {=IF($M$1="Manual",IFERROR(INDEX(CoStarSaleZipcodes,MATCH(O16,CoStarSaleName,0)),INDEX(YardiSaleZipcodes,MATCH(O16,YardiSaleName,0))),INDEX([1]!Output_Analysis_Data__2[ZIP],ROW()-2))} -> 76117 | U16: {=IF($M$1="Manual",IFERROR(INDEX(CoStarSaleUnits,MATCH(O16,CoStarSaleName,0)),INDEX(YardiSaleUnits,MATCH(O16,YardiSaleName,0))),INDEX([1]!Output_Analysis_Data__2[Unit Count],ROW()-2))} -> 88 | V16: {=IF($M$1="Manual","",INDEX([1]!Output_Analysis_Data__2[Distance (mi.)],ROW()-2))} -> 11.714591 | W16: {=IF($M$1="Manual",IFERROR(INDEX(CoStarSaleAvgUnitSize,MATCH(O16,CoStarSaleName,0)),INDEX(YardiSaleAvgUnitSize,MATCH(O16,YardiSaleName,0))),INDEX([1]!Output_Analysis_Data__2[Avg Unit SF],ROW()-2))} -> 886 | X16: {=IF($M$1="Manual",IFERROR(INDEX(CoStarSaleYearBuilt,MATCH(O16,CoStarSaleName,0)),INDEX(YardiSaleYearBuilt,MATCH(O16,YardiSaleName,0))),INDEX([1]!Output_Analysis_Data__2[Year Built],ROW()-2))} -> 1970 | Y16: {=IF($M$1="Manual",IF(AA16<>"",AA16,IF(AB16<>"",AB16,IF(AC16<>"",AC16,""))),INDEX([1]!Output_Analysis_Data__2[Sold Price],ROW()-2))} -> 10590000 | Z16: {=IF($M$1="Manual",IFERROR(INDEX(CoStarSaleDate,MATCH(O16,CoStarSaleName,0)),INDEX(YardiSaleDate,MATCH(O16,YardiSaleName,0))),INDEX([1]!Output_Analysis_Data__2[Sale Date],ROW()-2))} -> 45890 | AA16: =IFERROR(INDEX('[1]Agency Loan-Sale Comps'!$J$16:$J$37,MATCH('Comparable Grid'!AD16,'[1]Agency Loan-Sale Comps'!$A$16:$A$37,0),0),"") | AB16: =IFERROR(IF(INDEX(CoStarSalePriceTotal,MATCH(AD16,CoStarSaleCompLookup,0),0)=0,"",INDEX(CoStarSalePriceTotal,MATCH(AD16,CoStarSaleCompLookup,0),0)),"") | AC16: =IFERROR(IF(INDEX(YardiSalePriceTotal,MATCH(AD16,YardiSaleCompLookup,0),0)=0,"",INDEX(YardiSalePriceTotal,MATCH(AD16,YardiSaleCompLookup,0),0)),"") | AD16: =LEFT(Q16,FIND(" ",Q16,1)) -> 4812 | AE16: =AE15&IF($L16="x","x","") -> xxxxxx
C17: Unit Count | D17: =[1]Master!G33 -> 40 | E17: =IFERROR(INDEX($U$3:$U$52,MATCH("x",$AE$3:$AE$52,0),0),"") -> 278 | F17: =IFERROR(INDEX($U$3:$U$52,MATCH("xx",$AE$3:$AE$52,0),0),"") -> 410 | G17: =IFERROR(INDEX($U$3:$U$52,MATCH("xxx",$AE$3:$AE$52,0),0),"") -> 192 | H17: =IFERROR(INDEX($U$3:$U$52,MATCH("xxxx",$AE$3:$AE$52,0),0),"") -> 60 | I17: =IFERROR(INDEX($U$3:$U$52,MATCH("xxxxx",$AE$3:$AE$52,0),0),"") -> 90 | M17: =IF($M$1="Manual",IF(Y17="","No Sale Price Disclosed!",""),"") | N17: {=IF($M$1="Manual",IF(AA17<>"","Freddie/Fannie",IF(AB17<>"","CoStar",IF(AC17<>"","Yardi","N/A"))),INDEX([1]!Output_Analysis_Data__2[Info Source],ROW()-2))} -> Yardi | O17: {=IF($M$1="Manual",'[1]Sale Comps'!BY17,INDEX([1]!Output_Analysis_Data__2[Property Name],ROW()-2))} -> Ashton Apartment Homes | P17: =IFERROR(Y17/U17,"") -> 131578.95 | Q17: {=IF($M$1="Manual",IFERROR(INDEX(CoStarSaleAddress,MATCH(O17,CoStarSaleName,0)),INDEX(YardiSaleAddress,MATCH(O17,YardiSaleName,0))),INDEX([1]!Output_Analysis_Data__2[Property Address],ROW()-2))} -> 681 North Saginaw Blvd | R17: {=IF($M$1="Manual",IFERROR(INDEX(CoStarSaleCity,MATCH(O17,CoStarSaleName,0)),INDEX(YardiSaleCity,MATCH(O17,YardiSaleName,0))),INDEX([1]!Output_Analysis_Data__2[City],ROW()-2))} -> Saginaw | S17: {=IF($M$1="Manual",IFERROR(INDEX(CoStarSaleState,MATCH(O17,CoStarSaleName,0)),INDEX(YardiSaleState,MATCH(O17,YardiSaleName,0))),INDEX([1]!Output_Analysis_Data__2[State],ROW()-2))} -> TX | T17: {=IF($M$1="Manual",IFERROR(INDEX(CoStarSaleZipcodes,MATCH(O17,CoStarSaleName,0)),INDEX(YardiSaleZipcodes,MATCH(O17,YardiSaleName,0))),INDEX([1]!Output_Analysis_Data__2[ZIP],ROW()-2))} -> 76179 | U17: {=IF($M$1="Manual",IFERROR(INDEX(CoStarSaleUnits,MATCH(O17,CoStarSaleName,0)),INDEX(YardiSaleUnits,MATCH(O17,YardiSaleName,0))),INDEX([1]!Output_Analysis_Data__2[Unit Count],ROW()-2))} -> 152 | V17: {=IF($M$1="Manual","",INDEX([1]!Output_Analysis_Data__2[Distance (mi.)],ROW()-2))} -> 12.132617 | W17: {=IF($M$1="Manual",IFERROR(INDEX(CoStarSaleAvgUnitSize,MATCH(O17,CoStarSaleName,0)),INDEX(YardiSaleAvgUnitSize,MATCH(O17,YardiSaleName,0))),INDEX([1]!Output_Analysis_Data__2[Avg Unit SF],ROW()-2))} -> 774 | X17: {=IF($M$1="Manual",IFERROR(INDEX(CoStarSaleYearBuilt,MATCH(O17,CoStarSaleName,0)),INDEX(YardiSaleYearBuilt,MATCH(O17,YardiSaleName,0))),INDEX([1]!Output_Analysis_Data__2[Year Built],ROW()-2))} -> 1984 | Y17: {=IF($M$1="Manual",IF(AA17<>"",AA17,IF(AB17<>"",AB17,IF(AC17<>"",AC17,""))),INDEX([1]!Output_Analysis_Data__2[Sold Price],ROW()-2))} -> 20000000 | Z17: {=IF($M$1="Manual",IFERROR(INDEX(CoStarSaleDate,MATCH(O17,CoStarSaleName,0)),INDEX(YardiSaleDate,MATCH(O17,YardiSaleName,0))),INDEX([1]!Output_Analysis_Data__2[Sale Date],ROW()-2))} -> 45733 | AA17: =IFERROR(INDEX('[1]Agency Loan-Sale Comps'!$J$16:$J$37,MATCH('Comparable Grid'!AD17,'[1]Agency Loan-Sale Comps'!$A$16:$A$37,0),0),"") | AB17: =IFERROR(IF(INDEX(CoStarSalePriceTotal,MATCH(AD17,CoStarSaleCompLookup,0),0)=0,"",INDEX(CoStarSalePriceTotal,MATCH(AD17,CoStarSaleCompLookup,0),0)),"") | AC17: =IFERROR(IF(INDEX(YardiSalePriceTotal,MATCH(AD17,YardiSaleCompLookup,0),0)=0,"",INDEX(YardiSalePriceTotal,MATCH(AD17,YardiSaleCompLookup,0),0)),"") | AD17: =LEFT(Q17,FIND(" ",Q17,1)) -> 681 | AE17: =AE16&IF($L17="x","x","") -> xxxxxx
C18: Sale Price/Unit | E18: =IFERROR(E15/E17,"") -> 111510.79 | F18: =IFERROR(F15/F17,"") -> 101414.63 | G18: =IFERROR(G15/G17,"") -> 105729.17 | H18: =IFERROR(H15/H17,"") -> 92000 | I18: =IFERROR(I15/I17,"") -> 108888.89 | M18: =IF($M$1="Manual",IF(Y18="","No Sale Price Disclosed!",""),"") | N18: {=IF($M$1="Manual",IF(AA18<>"","Freddie/Fannie",IF(AB18<>"","CoStar",IF(AC18<>"","Yardi","N/A"))),INDEX([1]!Output_Analysis_Data__2[Info Source],ROW()-2))} -> Fannie | O18: {=IF($M$1="Manual",'[1]Sale Comps'!BY18,INDEX([1]!Output_Analysis_Data__2[Property Name],ROW()-2))} -> Oaks at Jane Lane | P18: =IFERROR(Y18/U18,"") -> 105733.94 | Q18: {=IF($M$1="Manual",IFERROR(INDEX(CoStarSaleAddress,MATCH(O18,CoStarSaleName,0)),INDEX(YardiSaleAddress,MATCH(O18,YardiSaleName,0))),INDEX([1]!Output_Analysis_Data__2[Property Address],ROW()-2))} -> 3001 Jane Lane | R18: {=IF($M$1="Manual",IFERROR(INDEX(CoStarSaleCity,MATCH(O18,CoStarSaleName,0)),INDEX(YardiSaleCity,MATCH(O18,YardiSaleName,0))),INDEX([1]!Output_Analysis_Data__2[City],ROW()-2))} -> Haltom City | S18: {=IF($M$1="Manual",IFERROR(INDEX(CoStarSaleState,MATCH(O18,CoStarSaleName,0)),INDEX(YardiSaleState,MATCH(O18,YardiSaleName,0))),INDEX([1]!Output_Analysis_Data__2[State],ROW()-2))} -> TX | T18: {=IF($M$1="Manual",IFERROR(INDEX(CoStarSaleZipcodes,MATCH(O18,CoStarSaleName,0)),INDEX(YardiSaleZipcodes,MATCH(O18,YardiSaleName,0))),INDEX([1]!Output_Analysis_Data__2[ZIP],ROW()-2))} -> 76117 | U18: {=IF($M$1="Manual",IFERROR(INDEX(CoStarSaleUnits,MATCH(O18,CoStarSaleName,0)),INDEX(YardiSaleUnits,MATCH(O18,YardiSaleName,0))),INDEX([1]!Output_Analysis_Data__2[Unit Count],ROW()-2))} -> 109 | V18: {=IF($M$1="Manual","",INDEX([1]!Output_Analysis_Data__2[Distance (mi.)],ROW()-2))} -> 12.547129 | W18: {=IF($M$1="Manual",IFERROR(INDEX(CoStarSaleAvgUnitSize,MATCH(O18,CoStarSaleName,0)),INDEX(YardiSaleAvgUnitSize,MATCH(O18,YardiSaleName,0))),INDEX([1]!Output_Analysis_Data__2[Avg Unit SF],ROW()-2))} -> 869 | X18: {=IF($M$1="Manual",IFERROR(INDEX(CoStarSaleYearBuilt,MATCH(O18,CoStarSaleName,0)),INDEX(YardiSaleYearBuilt,MATCH(O18,YardiSaleName,0))),INDEX([1]!Output_Analysis_Data__2[Year Built],ROW()-2))} -> 1969 | Y18: {=IF($M$1="Manual",IF(AA18<>"",AA18,IF(AB18<>"",AB18,IF(AC18<>"",AC18,""))),INDEX([1]!Output_Analysis_Data__2[Sold Price],ROW()-2))} -> 11525000 | Z18: {=IF($M$1="Manual",IFERROR(INDEX(CoStarSaleDate,MATCH(O18,CoStarSaleName,0)),INDEX(YardiSaleDate,MATCH(O18,YardiSaleName,0))),INDEX([1]!Output_Analysis_Data__2[Sale Date],ROW()-2))} -> 45733 | AA18: =IFERROR(INDEX('[1]Agency Loan-Sale Comps'!$J$16:$J$37,MATCH('Comparable Grid'!AD18,'[1]Agency Loan-Sale Comps'!$A$16:$A$37,0),0),"") | AB18: =IFERROR(IF(INDEX(CoStarSalePriceTotal,MATCH(AD18,CoStarSaleCompLookup,0),0)=0,"",INDEX(CoStarSalePriceTotal,MATCH(AD18,CoStarSaleCompLookup,0),0)),"") | AC18: =IFERROR(IF(INDEX(YardiSalePriceTotal,MATCH(AD18,YardiSaleCompLookup,0),0)=0,"",INDEX(YardiSalePriceTotal,MATCH(AD18,YardiSaleCompLookup,0),0)),"") | AD18: =LEFT(Q18,FIND(" ",Q18,1)) -> 3001 | AE18: =AE17&IF($L18="x","x","") -> xxxxxx
M19: =IF($M$1="Manual",IF(Y19="","No Sale Price Disclosed!",""),"") | N19: {=IF($M$1="Manual",IF(AA19<>"","Freddie/Fannie",IF(AB19<>"","CoStar",IF(AC19<>"","Yardi","N/A"))),INDEX([1]!Output_Analysis_Data__2[Info Source],ROW()-2))} -> Fannie | O19: {=IF($M$1="Manual",'[1]Sale Comps'!BY19,INDEX([1]!Output_Analysis_Data__2[Property Name],ROW()-2))} -> Luna Vista | P19: =IFERROR(Y19/U19,"") -> 113983.05 | Q19: {=IF($M$1="Manual",IFERROR(INDEX(CoStarSaleAddress,MATCH(O19,CoStarSaleName,0)),INDEX(YardiSaleAddress,MATCH(O19,YardiSaleName,0))),INDEX([1]!Output_Analysis_Data__2[Property Address],ROW()-2))} -> 5925 Callaston Lane | R19: {=IF($M$1="Manual",IFERROR(INDEX(CoStarSaleCity,MATCH(O19,CoStarSaleName,0)),INDEX(YardiSaleCity,MATCH(O19,YardiSaleName,0))),INDEX([1]!Output_Analysis_Data__2[City],ROW()-2))} -> Fort Worth | S19: {=IF($M$1="Manual",IFERROR(INDEX(CoStarSaleState,MATCH(O19,CoStarSaleName,0)),INDEX(YardiSaleState,MATCH(O19,YardiSaleName,0))),INDEX([1]!Output_Analysis_Data__2[State],ROW()-2))} -> TX | T19: {=IF($M$1="Manual",IFERROR(INDEX(CoStarSaleZipcodes,MATCH(O19,CoStarSaleName,0)),INDEX(YardiSaleZipcodes,MATCH(O19,YardiSaleName,0))),INDEX([1]!Output_Analysis_Data__2[ZIP],ROW()-2))} -> 76112 | U19: {=IF($M$1="Manual",IFERROR(INDEX(CoStarSaleUnits,MATCH(O19,CoStarSaleName,0)),INDEX(YardiSaleUnits,MATCH(O19,YardiSaleName,0))),INDEX([1]!Output_Analysis_Data__2[Unit Count],ROW()-2))} -> 236 | V19: {=IF($M$1="Manual","",INDEX([1]!Output_Analysis_Data__2[Distance (mi.)],ROW()-2))} -> 13.619964 | W19: {=IF($M$1="Manual",IFERROR(INDEX(CoStarSaleAvgUnitSize,MATCH(O19,CoStarSaleName,0)),INDEX(YardiSaleAvgUnitSize,MATCH(O19,YardiSaleName,0))),INDEX([1]!Output_Analysis_Data__2[Avg Unit SF],ROW()-2))} -> 786 | X19: {=IF($M$1="Manual",IFERROR(INDEX(CoStarSaleYearBuilt,MATCH(O19,CoStarSaleName,0)),INDEX(YardiSaleYearBuilt,MATCH(O19,YardiSaleName,0))),INDEX([1]!Output_Analysis_Data__2[Year Built],ROW()-2))} -> 1979 | Y19: {=IF($M$1="Manual",IF(AA19<>"",AA19,IF(AB19<>"",AB19,IF(AC19<>"",AC19,""))),INDEX([1]!Output_Analysis_Data__2[Sold Price],ROW()-2))} -> 26900000 | Z19: {=IF($M$1="Manual",IFERROR(INDEX(CoStarSaleDate,MATCH(O19,CoStarSaleName,0)),INDEX(YardiSaleDate,MATCH(O19,YardiSaleName,0))),INDEX([1]!Output_Analysis_Data__2[Sale Date],ROW()-2))} -> 45215 | AA19: =IFERROR(INDEX('[1]Agency Loan-Sale Comps'!$J$16:$J$37,MATCH('Comparable Grid'!AD19,'[1]Agency Loan-Sale Comps'!$A$16:$A$37,0),0),"") | AB19: =IFERROR(IF(INDEX(CoStarSalePriceTotal,MATCH(AD19,CoStarSaleCompLookup,0),0)=0,"",INDEX(CoStarSalePriceTotal,MATCH(AD19,CoStarSaleCompLookup,0),0)),"") | AC19: =IFERROR(IF(INDEX(YardiSalePriceTotal,MATCH(AD19,YardiSaleCompLookup,0),0)=0,"",INDEX(YardiSalePriceTotal,MATCH(AD19,YardiSaleCompLookup,0),0)),"") | AD19: =LEFT(Q19,FIND(" ",Q19,1)) -> 5925 | AE19: =AE18&IF($L19="x","x","") -> xxxxxx
C20: Adjustments | M20: =IF($M$1="Manual",IF(Y20="","No Sale Price Disclosed!",""),"") | N20: {=IF($M$1="Manual",IF(AA20<>"","Freddie/Fannie",IF(AB20<>"","CoStar",IF(AC20<>"","Yardi","N/A"))),INDEX([1]!Output_Analysis_Data__2[Info Source],ROW()-2))} -> Yardi | O20: {=IF($M$1="Manual",'[1]Sale Comps'!BY20,INDEX([1]!Output_Analysis_Data__2[Property Name],ROW()-2))} -> Rise Fossil Creek | P20: =IFERROR(Y20/U20,"") -> 154930.56 | Q20: {=IF($M$1="Manual",IFERROR(INDEX(CoStarSaleAddress,MATCH(O20,CoStarSaleName,0)),INDEX(YardiSaleAddress,MATCH(O20,YardiSaleName,0))),INDEX([1]!Output_Analysis_Data__2[Property Address],ROW()-2))} -> 5600 North Beach Street | R20: {=IF($M$1="Manual",IFERROR(INDEX(CoStarSaleCity,MATCH(O20,CoStarSaleName,0)),INDEX(YardiSaleCity,MATCH(O20,YardiSaleName,0))),INDEX([1]!Output_Analysis_Data__2[City],ROW()-2))} -> Haltom City | S20: {=IF($M$1="Manual",IFERROR(INDEX(CoStarSaleState,MATCH(O20,CoStarSaleName,0)),INDEX(YardiSaleState,MATCH(O20,YardiSaleName,0))),INDEX([1]!Output_Analysis_Data__2[State],ROW()-2))} -> TX | T20: {=IF($M$1="Manual",IFERROR(INDEX(CoStarSaleZipcodes,MATCH(O20,CoStarSaleName,0)),INDEX(YardiSaleZipcodes,MATCH(O20,YardiSaleName,0))),INDEX([1]!Output_Analysis_Data__2[ZIP],ROW()-2))} -> 76137 | U20: {=IF($M$1="Manual",IFERROR(INDEX(CoStarSaleUnits,MATCH(O20,CoStarSaleName,0)),INDEX(YardiSaleUnits,MATCH(O20,YardiSaleName,0))),INDEX([1]!Output_Analysis_Data__2[Unit Count],ROW()-2))} -> 288 | V20: {=IF($M$1="Manual","",INDEX([1]!Output_Analysis_Data__2[Distance (mi.)],ROW()-2))} -> 13.671819 | W20: {=IF($M$1="Manual",IFERROR(INDEX(CoStarSaleAvgUnitSize,MATCH(O20,CoStarSaleName,0)),INDEX(YardiSaleAvgUnitSize,MATCH(O20,YardiSaleName,0))),INDEX([1]!Output_Analysis_Data__2[Avg Unit SF],ROW()-2))} -> 744 | X20: {=IF($M$1="Manual",IFERROR(INDEX(CoStarSaleYearBuilt,MATCH(O20,CoStarSaleName,0)),INDEX(YardiSaleYearBuilt,MATCH(O20,YardiSaleName,0))),INDEX([1]!Output_Analysis_Data__2[Year Built],ROW()-2))} -> 1986 | Y20: {=IF($M$1="Manual",IF(AA20<>"",AA20,IF(AB20<>"",AB20,IF(AC20<>"",AC20,""))),INDEX([1]!Output_Analysis_Data__2[Sold Price],ROW()-2))} -> 44620000 | Z20: {=IF($M$1="Manual",IFERROR(INDEX(CoStarSaleDate,MATCH(O20,CoStarSaleName,0)),INDEX(YardiSaleDate,MATCH(O20,YardiSaleName,0))),INDEX([1]!Output_Analysis_Data__2[Sale Date],ROW()-2))} -> 45401 | AA20: =IFERROR(INDEX('[1]Agency Loan-Sale Comps'!$J$16:$J$37,MATCH('Comparable Grid'!AD20,'[1]Agency Loan-Sale Comps'!$A$16:$A$37,0),0),"") | AB20: =IFERROR(IF(INDEX(CoStarSalePriceTotal,MATCH(AD20,CoStarSaleCompLookup,0),0)=0,"",INDEX(CoStarSalePriceTotal,MATCH(AD20,CoStarSaleCompLookup,0),0)),"") | AC20: =IFERROR(IF(INDEX(YardiSalePriceTotal,MATCH(AD20,YardiSaleCompLookup,0),0)=0,"",INDEX(YardiSalePriceTotal,MATCH(AD20,YardiSaleCompLookup,0),0)),"") | AD20: =LEFT(Q20,FIND(" ",Q20,1)) -> 5600 | AE20: =AE19&IF($L20="x","x","") -> xxxxxx
