Workbook
Name GeneratedBy: #REF!
Name masterkeytable: Masterkey!$A$1:$B$50
Name rediq_dealname: 'Trailing Financials'!$A$1
Name rediq_lineitems_overview: 'Trailing Financials'!#REF!

Sheet Trailing Financials
A1: Harvest Moon
A2: Trailing 12 Month Income/Expense
B3: Monthly | C3: Monthly | D3: Monthly | E3: Monthly | F3: Monthly | G3: Monthly | H3: Monthly | I3: Monthly | J3: Monthly | K3: Monthly | L3: Monthly | M3: Monthly
A4: {=Final_T_12[category]} -> Account | B4: {=Final_T_12[date1]} -> 45809 | C4: {=Final_T_12[date2]} -> 45839 | D4: {=Final_T_12[date3]} -> 45870 | E4: {=Final_T_12[date4]} -> 45901 | F4: {=Final_T_12[date5]} -> 45931 | G4: {=Final_T_12[date6]} -> 45962 | H4: {=Final_T_12[date7]} -> 45992 | I4: {=Final_T_12[date8]} -> 46023 | J4: {=Final_T_12[date9]} -> 46054 | K4: {=Final_T_12[date10]} -> 46082 | L4: {=Final_T_12[date11]} -> 46113 | M4: {=Final_T_12[date12]} -> 46143 | N4: {=Final_T_12[total]} -> Total
A6: Rental Income
A7: 4100100 Apartment Income | B7: 98319 | C7: 98319 | D7: 98319 | E7: 98319 | F7: 98319 | G7: 98319 | H7: 98319 | I7: 98319 | J7: 98319 | K7: 98319 | L7: 98319 | M7: 98319 | N7: 1179828
A8: (Loss to Lease) / Gain to Lease
A9: 4100101 Gain/Loss to Lease | B9: -7470 | C9: -5694 | D9: -4199 | E9: -3850 | F9: -4278 | G9: -4164 | H9: -4094 | I9: -5332 | J9: -3695 | K9: -3174 | L9: -3385 | M9: -3248 | N9: -52583
A10: Vacancy
A11: 4100105 Model Units | B11: 0 | C11: 0 | D11: 0 | E11: 0 | F11: 0 | G11: 0 | H11: 0 | I11: 0 | J11: 0 | K11: 0 | L11: -1.83 | M11: -5 | N11: -6.83
A12: Non-Revenue/Concessions
A13: 4100106 Vacancy Loss | B13: -13725.89 | C13: -14532.17 | D13: -25005.29 | E13: -18833.49 | F13: -7135.31 | G13: -3387.5 | H13: -2806.89 | I13: -105.42 | J13: -1181.42 | K13: -2687.1 | L13: -3492.74 | M13: -2583 | N13: -95476.22
A14: 4100107 Concessions | B14: 0 | C14: 0 | D14: 0 | E14: 0 | F14: -99.86 | G14: 0 | H14: 0 | I14: 0 | J14: 0 | K14: 0 | L14: 0 | M14: 0 | N14: -99.86
A15: Bad Debt
A16: 4100112 Net Prepaids | B16: 732.09 | C16: 5.94 | D16: -2385.74 | E16: 789.69 | F16: 1159.41 | G16: -2248.45 | H16: 960.86 | I16: 64.26 | J16: -1337.56 | K16: -133.27 | L16: 865.34 | M16: -785.12 | N16: -2312.55
A17: 4100113 Net Delinquency | B17: -7210.84 | C17: -15776.46 | D17: -13010.57 | E17: 1307.36 | F17: -4534.37 | G17: 2586.83 | H17: -1844.19 | I17: -1177.15 | J17: 428.94 | K17: -1032.18 | L17: 66.59 | M17: -368.77 | N17: -40564.81
A18: RUBS - Water/Sewer
A19: 4101800 Water Reimbursement | B19: 0 | C19: 0 | D19: 0 | E19: 0 | F19: 2670 | G19: 4240 | H19: 4151 | I19: 0 | J19: 0 | K19: 0 | L19: 0 | M19: 0 | N19: 11061
A20: RUBS - Electric/Gas/Other
A21: 4101830 Trash Reimbursement | B21: 1148.04 | C21: 1127.42 | D21: 818.24 | E21: 919.17 | F21: 760.65 | G21: 705.83 | H21: 760 | I21: 0 | J21: 0 | K21: 0 | L21: 0 | M21: 0 | N21: 6239.35
A22: Other Income
A23: Other Income | B23: 0 | C23: 0 | D23: 0 | E23: 0 | F23: 0 | G23: 0 | H23: 0 | I23: 0 | J23: 0 | K23: 0 | L23: 0 | M23: 0 | N23: 0
A24: 4100200 Month to Month | B24: 0 | C24: 0 | D24: 0 | E24: 0 | F24: 135.89 | G24: 400 | H24: 0 | I24: 0 | J24: 0 | K24: 0 | L24: 0 | M24: 0 | N24: 535.89
A25: 4100600 Cleaning fee/Damage Fee | B25: 0 | C25: 0 | D25: 28.7 | E25: 0 | F25: 0 | G25: 0 | H25: 0 | I25: 0 | J25: 0 | K25: 0 | L25: 0 | M25: 0 | N25: 28.7
A26: 4100700 Carport Parking | B26: 105 | C26: 210 | D26: 105 | E26: 141.17 | F26: 210 | G26: 148.17 | H26: 210 | I26: 175 | J26: 140 | K26: 175 | L26: 175 | M26: 175 | N26: 1969.34
A27: 4100800 Pet Fee | B27: 180 | C27: 180 | D27: 135 | E27: 190 | F27: 145.2 | G27: 120 | H27: 120 | I27: 120 | J27: 145 | K27: 160 | L27: 160 | M27: 185 | N27: 1840.2
A28: 4100900 Deposit Forfeiture | B28: 0 | C28: 4500 | D28: 3499 | E28: 350 | F28: 0 | G28: 0 | H28: 0 | I28: 2440 | J28: 0 | K28: 0 | L28: 404.5 | M28: 718.22 | N28: 11911.72
A29: 4101100 Late Charges | B29: 582 | C29: 339.07 | D29: 64.77 | E29: 949.5 | F29: 410 | G29: 1474 | H29: 969 | I29: 1003.8 | J29: 863.5 | K29: 1166.4 | L29: 104.9 | M29: 629.5 | N29: 8556.44
A30: 4101200 NSF Charges | B30: 50 | C30: 0 | D30: 7 | E30: 93 | F30: 0 | G30: 0 | H30: 100 | I30: 200 | J30: 150 | K30: 50 | L30: 50 | M30: 0 | N30: 700
A31: 4101400 Application Fees | B31: 400 | C31: 390 | D31: 149 | E31: 1347 | F31: 660 | G31: 0 | H31: 75 | I31: 0 | J31: 0 | K31: 225 | L31: 375 | M31: 100 | N31: 3721
A32: 4101500 Washer/Dryer Income | B32: 376.07 | C32: 480 | D32: 318.23 | E32: 952.5 | F32: 1135.2 | G32: 1813.87 | H32: 1627.41 | I32: 1850.61 | J32: 1627.42 | K32: 1600.97 | L32: 1633.17 | M32: 1786.45 | N32: 15201.9
A33: 4101600 Administrative Fee | B33: 420 | C33: 0 | D33: 149 | E33: 637 | F33: 400 | G33: 0 | H33: 0 | I33: 110 | J33: 10 | K33: 110 | L33: 300 | M33: -95 | N33: 2041
A34: 4101835 Valet Trash Reimbursement | B34: 44.84 | C34: 125.97 | D34: 251.61 | E34: 619.77 | F34: 834.89 | G34: 1166.5 | H34: 1060.48 | I34: 0 | J34: 0 | K34: 0 | L34: 0 | M34: 0 | N34: 4104.06
... A39: Total Revenue | B39: 74884.47 | C39: 70655.25 | D39: 60080.61 | E39: 85315.94 | F39: 92114.84 | G39: 102675.02 | H39: 101054.77 | I39: 106890.72 | J39: 104771.09 | K39: 103805.77 | L39: 103488.1 | M39: 102709.24 | N39: 1108445.8
A41: Expense
A42: Contract Services
A43: 5500200 Equipment Rental and Expense | B43: 0 | C43: 0 | D43: 0 | E43: 0 | F43: 0 | G43: 0 | H43: 1604.27 | I43: 0 | J43: 0 | K43: 0 | L43: 0 | M43: 392 | N43: 1996.27
A44: 5500300 Landscaping | B44: 811.88 | C44: 811.88 | D44: 811.88 | E44: 811.88 | F44: 811.88 | G44: 811.88 | H44: 811.88 | I44: 811.88 | J44: 811.88 | K44: 811.88 | L44: 811.88 | M44: 811.88 | N44: 9742.56
A45: 5500350 Landscaping Seasonal | B45: 0 | C45: 0 | D45: 447.55 | E45: 0 | F45: 0 | G45: 0 | H45: 0 | I45: 0 | J45: 0 | K45: 0 | L45: 0 | M45: 0 | N45: 447.55
A46: 5500700 Pest Control | B46: 0 | C46: 0 | D46: 107.98 | E46: 0 | F46: 363.97 | G46: 107.98 | H46: 107.98 | I46: 118.78 | J46: 0 | K46: 237.56 | L46: 0 | M46: 237.56 | N46: 1281.81
...

Sheet RawData
B1: Total Revenue Check | C1: =SUMIFS(C6:C1041,$A$6:$A$1041,"r")+SUMIFS(C6:C1041,$A$6:$A$1041,"ll")+SUMIFS(C6:C1041,$A$6:$A$1041,"bd")+SUMIFS(C6:C1041,$A$6:$A$1041,"v")+SUMIFS(C6:C1041,$A$6:$A$1041,"nr")+SUMIFS(C6:C1041,$A$6:$A$1041,"oi")+SUMIFS(C6:C1041,$A$6:$A$1041,"rt")+SUMIFS(C6:C1041,$A$6:$A$1041,"ro")+SUMIFS(C6:C1041,$A$6:$A$1041,"rw")-SUMIFS(C6:C1041,$A$6:$A$1041,"rev") -> 0 | D1: =SUMIFS(D6:D1041,$A$6:$A$1041,"r")+SUMIFS(D6:D1041,$A$6:$A$1041,"ll")+SUMIFS(D6:D1041,$A$6:$A$1041,"bd")+SUMIFS(D6:D1041,$A$6:$A$1041,"v")+SUMIFS(D6:D1041,$A$6:$A$1041,"nr")+SUMIFS(D6:D1041,$A$6:$A$1041,"oi")+SUMIFS(D6:D1041,$A$6:$A$1041,"rt")+SUMIFS(D6:D1041,$A$6:$A$1041,"ro")+SUMIFS(D6:D1041,$A$6:$A$1041,"rw")-SUMIFS(D6:D1041,$A$6:$A$1041,"rev") -> 0 | E1: =SUMIFS(E6:E1041,$A$6:$A$1041,"r")+SUMIFS(E6:E1041,$A$6:$A$1041,"ll")+SUMIFS(E6:E1041,$A$6:$A$1041,"bd")+SUMIFS(E6:E1041,$A$6:$A$1041,"v")+SUMIFS(E6:E1041,$A$6:$A$1041,"nr")+SUMIFS(E6:E1041,$A$6:$A$1041,"oi")+SUMIFS(E6:E1041,$A$6:$A$1041,"rt")+SUMIFS(E6:E1041,$A$6:$A$1041,"ro")+SUMIFS(E6:E1041,$A$6:$A$1041,"rw")-SUMIFS(E6:E1041,$A$6:$A$1041,"rev") -> 0 | F1: =SUMIFS(F6:F1041,$A$6:$A$1041,"r")+SUMIFS(F6:F1041,$A$6:$A$1041,"ll")+SUMIFS(F6:F1041,$A$6:$A$1041,"bd")+SUMIFS(F6:F1041,$A$6:$A$1041,"v")+SUMIFS(F6:F1041,$A$6:$A$1041,"nr")+SUMIFS(F6:F1041,$A$6:$A$1041,"oi")+SUMIFS(F6:F1041,$A$6:$A$1041,"rt")+SUMIFS(F6:F1041,$A$6:$A$1041,"ro")+SUMIFS(F6:F1041,$A$6:$A$1041,"rw")-SUMIFS(F6:F1041,$A$6:$A$1041,"rev") -> 0 | G1: =SUMIFS(G6:G1041,$A$6:$A$1041,"r")+SUMIFS(G6:G1041,$A$6:$A$1041,"ll")+SUMIFS(G6:G1041,$A$6:$A$1041,"bd")+SUMIFS(G6:G1041,$A$6:$A$1041,"v")+SUMIFS(G6:G1041,$A$6:$A$1041,"nr")+SUMIFS(G6:G1041,$A$6:$A$1041,"oi")+SUMIFS(G6:G1041,$A$6:$A$1041,"rt")+SUMIFS(G6:G1041,$A$6:$A$1041,"ro")+SUMIFS(G6:G1041,$A$6:$A$1041,"rw")-SUMIFS(G6:G1041,$A$6:$A$1041,"rev") -> 0 | H1: =SUMIFS(H6:H1041,$A$6:$A$1041,"r")+SUMIFS(H6:H1041,$A$6:$A$1041,"ll")+SUMIFS(H6:H1041,$A$6:$A$1041,"bd")+SUMIFS(H6:H1041,$A$6:$A$1041,"v")+SUMIFS(H6:H1041,$A$6:$A$1041,"nr")+SUMIFS(H6:H1041,$A$6:$A$1041,"oi")+SUMIFS(H6:H1041,$A$6:$A$1041,"rt")+SUMIFS(H6:H1041,$A$6:$A$1041,"ro")+SUMIFS(H6:H1041,$A$6:$A$1041,"rw")-SUMIFS(H6:H1041,$A$6:$A$1041,"rev") -> 0 | I1: =SUMIFS(I6:I1041,$A$6:$A$1041,"r")+SUMIFS(I6:I1041,$A$6:$A$1041,"ll")+SUMIFS(I6:I1041,$A$6:$A$1041,"bd")+SUMIFS(I6:I1041,$A$6:$A$1041,"v")+SUMIFS(I6:I1041,$A$6:$A$1041,"nr")+SUMIFS(I6:I1041,$A$6:$A$1041,"oi")+SUMIFS(I6:I1041,$A$6:$A$1041,"rt")+SUMIFS(I6:I1041,$A$6:$A$1041,"ro")+SUMIFS(I6:I1041,$A$6:$A$1041,"rw")-SUMIFS(I6:I1041,$A$6:$A$1041,"rev") -> 0 | J1: =SUMIFS(J6:J1041,$A$6:$A$1041,"r")+SUMIFS(J6:J1041,$A$6:$A$1041,"ll")+SUMIFS(J6:J1041,$A$6:$A$1041,"bd")+SUMIFS(J6:J1041,$A$6:$A$1041,"v")+SUMIFS(J6:J1041,$A$6:$A$1041,"nr")+SUMIFS(J6:J1041,$A$6:$A$1041,"oi")+SUMIFS(J6:J1041,$A$6:$A$1041,"rt")+SUMIFS(J6:J1041,$A$6:$A$1041,"ro")+SUMIFS(J6:J1041,$A$6:$A$1041,"rw")-SUMIFS(J6:J1041,$A$6:$A$1041,"rev") -> 0 | ... O1: =SUMIFS(O6:O1041,$A$6:$A$1041,"r")+SUMIFS(O6:O1041,$A$6:$A$1041,"ll")+SUMIFS(O6:O1041,$A$6:$A$1041,"bd")+SUMIFS(O6:O1041,$A$6:$A$1041,"v")+SUMIFS(O6:O1041,$A$6:$A$1041,"nr")+SUMIFS(O6:O1041,$A$6:$A$1041,"oi")+SUMIFS(O6:O1041,$A$6:$A$1041,"rt")+SUMIFS(O6:O1041,$A$6:$A$1041,"ro")+SUMIFS(O6:O1041,$A$6:$A$1041,"rw")-SUMIFS(O6:O1041,$A$6:$A$1041,"rev") -> 0 | Q1: should be 0
B2: Expense Check | C2: =SUMIFS(C6:C1041,$A$6:$A$1041,"ad")+SUMIFS(C6:C1041,$A$6:$A$1041,"m")+SUMIFS(C6:C1041,$A$6:$A$1041,"cs")+SUMIFS(C6:C1041,$A$6:$A$1041,"rm")+SUMIFS(C6:C1041,$A$6:$A$1041,"pr")+SUMIFS(C6:C1041,$A$6:$A$1041,"e")+SUMIFS(C6:C1041,$A$6:$A$1041,"w")+SUMIFS(C6:C1041,$A$6:$A$1041,"o")+SUMIFS(C6:C1041,$A$6:$A$1041,"tr")+SUMIFS(C6:C1041,$A$6:$A$1041,"i")+SUMIFS(C6:C1041,$A$6:$A$1041,"tx")+SUMIFS(C6:C1041,$A$6:$A$1041,"mf")-SUMIFS(C6:C1041,$A$6:$A$1041,"exp") -> 0 | D2: =SUMIFS(D6:D1041,$A$6:$A$1041,"ad")+SUMIFS(D6:D1041,$A$6:$A$1041,"m")+SUMIFS(D6:D1041,$A$6:$A$1041,"cs")+SUMIFS(D6:D1041,$A$6:$A$1041,"rm")+SUMIFS(D6:D1041,$A$6:$A$1041,"pr")+SUMIFS(D6:D1041,$A$6:$A$1041,"e")+SUMIFS(D6:D1041,$A$6:$A$1041,"w")+SUMIFS(D6:D1041,$A$6:$A$1041,"o")+SUMIFS(D6:D1041,$A$6:$A$1041,"tr")+SUMIFS(D6:D1041,$A$6:$A$1041,"i")+SUMIFS(D6:D1041,$A$6:$A$1041,"tx")+SUMIFS(D6:D1041,$A$6:$A$1041,"mf")-SUMIFS(D6:D1041,$A$6:$A$1041,"exp") -> 0 | E2: =SUMIFS(E6:E1041,$A$6:$A$1041,"ad")+SUMIFS(E6:E1041,$A$6:$A$1041,"m")+SUMIFS(E6:E1041,$A$6:$A$1041,"cs")+SUMIFS(E6:E1041,$A$6:$A$1041,"rm")+SUMIFS(E6:E1041,$A$6:$A$1041,"pr")+SUMIFS(E6:E1041,$A$6:$A$1041,"e")+SUMIFS(E6:E1041,$A$6:$A$1041,"w")+SUMIFS(E6:E1041,$A$6:$A$1041,"o")+SUMIFS(E6:E1041,$A$6:$A$1041,"tr")+SUMIFS(E6:E1041,$A$6:$A$1041,"i")+SUMIFS(E6:E1041,$A$6:$A$1041,"tx")+SUMIFS(E6:E1041,$A$6:$A$1041,"mf")-SUMIFS(E6:E1041,$A$6:$A$1041,"exp") -> 0 | F2: =SUMIFS(F6:F1041,$A$6:$A$1041,"ad")+SUMIFS(F6:F1041,$A$6:$A$1041,"m")+SUMIFS(F6:F1041,$A$6:$A$1041,"cs")+SUMIFS(F6:F1041,$A$6:$A$1041,"rm")+SUMIFS(F6:F1041,$A$6:$A$1041,"pr")+SUMIFS(F6:F1041,$A$6:$A$1041,"e")+SUMIFS(F6:F1041,$A$6:$A$1041,"w")+SUMIFS(F6:F1041,$A$6:$A$1041,"o")+SUMIFS(F6:F1041,$A$6:$A$1041,"tr")+SUMIFS(F6:F1041,$A$6:$A$1041,"i")+SUMIFS(F6:F1041,$A$6:$A$1041,"tx")+SUMIFS(F6:F1041,$A$6:$A$1041,"mf")-SUMIFS(F6:F1041,$A$6:$A$1041,"exp") -> 0 | G2: =SUMIFS(G6:G1041,$A$6:$A$1041,"ad")+SUMIFS(G6:G1041,$A$6:$A$1041,"m")+SUMIFS(G6:G1041,$A$6:$A$1041,"cs")+SUMIFS(G6:G1041,$A$6:$A$1041,"rm")+SUMIFS(G6:G1041,$A$6:$A$1041,"pr")+SUMIFS(G6:G1041,$A$6:$A$1041,"e")+SUMIFS(G6:G1041,$A$6:$A$1041,"w")+SUMIFS(G6:G1041,$A$6:$A$1041,"o")+SUMIFS(G6:G1041,$A$6:$A$1041,"tr")+SUMIFS(G6:G1041,$A$6:$A$1041,"i")+SUMIFS(G6:G1041,$A$6:$A$1041,"tx")+SUMIFS(G6:G1041,$A$6:$A$1041,"mf")-SUMIFS(G6:G1041,$A$6:$A$1041,"exp") -> 0 | H2: =SUMIFS(H6:H1041,$A$6:$A$1041,"ad")+SUMIFS(H6:H1041,$A$6:$A$1041,"m")+SUMIFS(H6:H1041,$A$6:$A$1041,"cs")+SUMIFS(H6:H1041,$A$6:$A$1041,"rm")+SUMIFS(H6:H1041,$A$6:$A$1041,"pr")+SUMIFS(H6:H1041,$A$6:$A$1041,"e")+SUMIFS(H6:H1041,$A$6:$A$1041,"w")+SUMIFS(H6:H1041,$A$6:$A$1041,"o")+SUMIFS(H6:H1041,$A$6:$A$1041,"tr")+SUMIFS(H6:H1041,$A$6:$A$1041,"i")+SUMIFS(H6:H1041,$A$6:$A$1041,"tx")+SUMIFS(H6:H1041,$A$6:$A$1041,"mf")-SUMIFS(H6:H1041,$A$6:$A$1041,"exp") -> 0 | I2: =SUMIFS(I6:I1041,$A$6:$A$1041,"ad")+SUMIFS(I6:I1041,$A$6:$A$1041,"m")+SUMIFS(I6:I1041,$A$6:$A$1041,"cs")+SUMIFS(I6:I1041,$A$6:$A$1041,"rm")+SUMIFS(I6:I1041,$A$6:$A$1041,"pr")+SUMIFS(I6:I1041,$A$6:$A$1041,"e")+SUMIFS(I6:I1041,$A$6:$A$1041,"w")+SUMIFS(I6:I1041,$A$6:$A$1041,"o")+SUMIFS(I6:I1041,$A$6:$A$1041,"tr")+SUMIFS(I6:I1041,$A$6:$A$1041,"i")+SUMIFS(I6:I1041,$A$6:$A$1041,"tx")+SUMIFS(I6:I1041,$A$6:$A$1041,"mf")-SUMIFS(I6:I1041,$A$6:$A$1041,"exp") -> 0 | J2: =SUMIFS(J6:J1041,$A$6:$A$1041,"ad")+SUMIFS(J6:J1041,$A$6:$A$1041,"m")+SUMIFS(J6:J1041,$A$6:$A$1041,"cs")+SUMIFS(J6:J1041,$A$6:$A$1041,"rm")+SUMIFS(J6:J1041,$A$6:$A$1041,"pr")+SUMIFS(J6:J1041,$A$6:$A$1041,"e")+SUMIFS(J6:J1041,$A$6:$A$1041,"w")+SUMIFS(J6:J1041,$A$6:$A$1041,"o")+SUMIFS(J6:J1041,$A$6:$A$1041,"tr")+SUMIFS(J6:J1041,$A$6:$A$1041,"i")+SUMIFS(J6:J1041,$A$6:$A$1041,"tx")+SUMIFS(J6:J1041,$A$6:$A$1041,"mf")-SUMIFS(J6:J1041,$A$6:$A$1041,"exp") -> 0 | ... O2: =SUMIFS(O6:O1041,$A$6:$A$1041,"ad")+SUMIFS(O6:O1041,$A$6:$A$1041,"m")+SUMIFS(O6:O1041,$A$6:$A$1041,"cs")+SUMIFS(O6:O1041,$A$6:$A$1041,"rm")+SUMIFS(O6:O1041,$A$6:$A$1041,"pr")+SUMIFS(O6:O1041,$A$6:$A$1041,"e")+SUMIFS(O6:O1041,$A$6:$A$1041,"w")+SUMIFS(O6:O1041,$A$6:$A$1041,"o")+SUMIFS(O6:O1041,$A$6:$A$1041,"tr")+SUMIFS(O6:O1041,$A$6:$A$1041,"i")+SUMIFS(O6:O1041,$A$6:$A$1041,"tx")+SUMIFS(O6:O1041,$A$6:$A$1041,"mf")-SUMIFS(O6:O1041,$A$6:$A$1041,"exp") -> 0
B3: NOI Check | C3: =(SUMIFS(C6:C1041,$A$6:$A$1041,"r")+SUMIFS(C6:C1041,$A$6:$A$1041,"ll")+SUMIFS(C6:C1041,$A$6:$A$1041,"bd")+SUMIFS(C6:C1041,$A$6:$A$1041,"v")+SUMIFS(C6:C1041,$A$6:$A$1041,"nr")+SUMIFS(C6:C1041,$A$6:$A$1041,"oi")+SUMIFS(C6:C1041,$A$6:$A$1041,"rt")+SUMIFS(C6:C1041,$A$6:$A$1041,"ro")+SUMIFS(C6:C1041,$A$6:$A$1041,"rw"))-(SUMIFS(C6:C1041,$A$6:$A$1041,"ad")+SUMIFS(C6:C1041,$A$6:$A$1041,"m")+SUMIFS(C6:C1041,$A$6:$A$1041,"cs")+SUMIFS(C6:C1041,$A$6:$A$1041,"rm")+SUMIFS(C6:C1041,$A$6:$A$1041,"pr")+SUMIFS(C6:C1041,$A$6:$A$1041,"e")+SUMIFS(C6:C1041,$A$6:$A$1041,"w")+SUMIFS(C6:C1041,$A$6:$A$1041,"o")+SUMIFS(C6:C1041,$A$6:$A$1041,"tr")+SUMIFS(C6:C1041,$A$6:$A$1041,"i")+SUMIFS(C6:C1041,$A$6:$A$1041,"tx")+SUMIFS(C6:C1041,$A$6:$A$1041,"mf"))-SUMIFS(C6:C1041,$A$6:$A$1041,"noi") -> 0 | D3: =(SUMIFS(D6:D1041,$A$6:$A$1041,"r")+SUMIFS(D6:D1041,$A$6:$A$1041,"ll")+SUMIFS(D6:D1041,$A$6:$A$1041,"bd")+SUMIFS(D6:D1041,$A$6:$A$1041,"v")+SUMIFS(D6:D1041,$A$6:$A$1041,"nr")+SUMIFS(D6:D1041,$A$6:$A$1041,"oi")+SUMIFS(D6:D1041,$A$6:$A$1041,"rt")+SUMIFS(D6:D1041,$A$6:$A$1041,"ro")+SUMIFS(D6:D1041,$A$6:$A$1041,"rw"))-(SUMIFS(D6:D1041,$A$6:$A$1041,"ad")+SUMIFS(D6:D1041,$A$6:$A$1041,"m")+SUMIFS(D6:D1041,$A$6:$A$1041,"cs")+SUMIFS(D6:D1041,$A$6:$A$1041,"rm")+SUMIFS(D6:D1041,$A$6:$A$1041,"pr")+SUMIFS(D6:D1041,$A$6:$A$1041,"e")+SUMIFS(D6:D1041,$A$6:$A$1041,"w")+SUMIFS(D6:D1041,$A$6:$A$1041,"o")+SUMIFS(D6:D1041,$A$6:$A$1041,"tr")+SUMIFS(D6:D1041,$A$6:$A$1041,"i")+SUMIFS(D6:D1041,$A$6:$A$1041,"tx")+SUMIFS(D6:D1041,$A$6:$A$1041,"mf"))-SUMIFS(D6:D1041,$A$6:$A$1041,"noi") -> 0 | E3: =(SUMIFS(E6:E1041,$A$6:$A$1041,"r")+SUMIFS(E6:E1041,$A$6:$A$1041,"ll")+SUMIFS(E6:E1041,$A$6:$A$1041,"bd")+SUMIFS(E6:E1041,$A$6:$A$1041,"v")+SUMIFS(E6:E1041,$A$6:$A$1041,"nr")+SUMIFS(E6:E1041,$A$6:$A$1041,"oi")+SUMIFS(E6:E1041,$A$6:$A$1041,"rt")+SUMIFS(E6:E1041,$A$6:$A$1041,"ro")+SUMIFS(E6:E1041,$A$6:$A$1041,"rw"))-(SUMIFS(E6:E1041,$A$6:$A$1041,"ad")+SUMIFS(E6:E1041,$A$6:$A$1041,"m")+SUMIFS(E6:E1041,$A$6:$A$1041,"cs")+SUMIFS(E6:E1041,$A$6:$A$1041,"rm")+SUMIFS(E6:E1041,$A$6:$A$1041,"pr")+SUMIFS(E6:E1041,$A$6:$A$1041,"e")+SUMIFS(E6:E1041,$A$6:$A$1041,"w")+SUMIFS(E6:E1041,$A$6:$A$1041,"o")+SUMIFS(E6:E1041,$A$6:$A$1041,"tr")+SUMIFS(E6:E1041,$A$6:$A$1041,"i")+SUMIFS(E6:E1041,$A$6:$A$1041,"tx")+SUMIFS(E6:E1041,$A$6:$A$1041,"mf"))-SUMIFS(E6:E1041,$A$6:$A$1041,"noi") -> 0 | F3: =(SUMIFS(F6:F1041,$A$6:$A$1041,"r")+SUMIFS(F6:F1041,$A$6:$A$1041,"ll")+SUMIFS(F6:F1041,$A$6:$A$1041,"bd")+SUMIFS(F6:F1041,$A$6:$A$1041,"v")+SUMIFS(F6:F1041,$A$6:$A$1041,"nr")+SUMIFS(F6:F1041,$A$6:$A$1041,"oi")+SUMIFS(F6:F1041,$A$6:$A$1041,"rt")+SUMIFS(F6:F1041,$A$6:$A$1041,"ro")+SUMIFS(F6:F1041,$A$6:$A$1041,"rw"))-(SUMIFS(F6:F1041,$A$6:$A$1041,"ad")+SUMIFS(F6:F1041,$A$6:$A$1041,"m")+SUMIFS(F6:F1041,$A$6:$A$1041,"cs")+SUMIFS(F6:F1041,$A$6:$A$1041,"rm")+SUMIFS(F6:F1041,$A$6:$A$1041,"pr")+SUMIFS(F6:F1041,$A$6:$A$1041,"e")+SUMIFS(F6:F1041,$A$6:$A$1041,"w")+SUMIFS(F6:F1041,$A$6:$A$1041,"o")+SUMIFS(F6:F1041,$A$6:$A$1041,"tr")+SUMIFS(F6:F1041,$A$6:$A$1041,"i")+SUMIFS(F6:F1041,$A$6:$A$1041,"tx")+SUMIFS(F6:F1041,$A$6:$A$1041,"mf"))-SUMIFS(F6:F1041,$A$6:$A$1041,"noi") -> 0 | G3: =(SUMIFS(G6:G1041,$A$6:$A$1041,"r")+SUMIFS(G6:G1041,$A$6:$A$1041,"ll")+SUMIFS(G6:G1041,$A$6:$A$1041,"bd")+SUMIFS(G6:G1041,$A$6:$A$1041,"v")+SUMIFS(G6:G1041,$A$6:$A$1041,"nr")+SUMIFS(G6:G1041,$A$6:$A$1041,"oi")+SUMIFS(G6:G1041,$A$6:$A$1041,"rt")+SUMIFS(G6:G1041,$A$6:$A$1041,"ro")+SUMIFS(G6:G1041,$A$6:$A$1041,"rw"))-(SUMIFS(G6:G1041,$A$6:$A$1041,"ad")+SUMIFS(G6:G1041,$A$6:$A$1041,"m")+SUMIFS(G6:G1041,$A$6:$A$1041,"cs")+SUMIFS(G6:G1041,$A$6:$A$1041,"rm")+SUMIFS(G6:G1041,$A$6:$A$1041,"pr")+SUMIFS(G6:G1041,$A$6:$A$1041,"e")+SUMIFS(G6:G1041,$A$6:$A$1041,"w")+SUMIFS(G6:G1041,$A$6:$A$1041,"o")+SUMIFS(G6:G1041,$A$6:$A$1041,"tr")+SUMIFS(G6:G1041,$A$6:$A$1041,"i")+SUMIFS(G6:G1041,$A$6:$A$1041,"tx")+SUMIFS(G6:G1041,$A$6:$A$1041,"mf"))-SUMIFS(G6:G1041,$A$6:$A$1041,"noi") -> 0 | H3: =(SUMIFS(H6:H1041,$A$6:$A$1041,"r")+SUMIFS(H6:H1041,$A$6:$A$1041,"ll")+SUMIFS(H6:H1041,$A$6:$A$1041,"bd")+SUMIFS(H6:H1041,$A$6:$A$1041,"v")+SUMIFS(H6:H1041,$A$6:$A$1041,"nr")+SUMIFS(H6:H1041,$A$6:$A$1041,"oi")+SUMIFS(H6:H1041,$A$6:$A$1041,"rt")+SUMIFS(H6:H1041,$A$6:$A$1041,"ro")+SUMIFS(H6:H1041,$A$6:$A$1041,"rw"))-(SUMIFS(H6:H1041,$A$6:$A$1041,"ad")+SUMIFS(H6:H1041,$A$6:$A$1041,"m")+SUMIFS(H6:H1041,$A$6:$A$1041,"cs")+SUMIFS(H6:H1041,$A$6:$A$1041,"rm")+SUMIFS(H6:H1041,$A$6:$A$1041,"pr")+SUMIFS(H6:H1041,$A$6:$A$1041,"e")+SUMIFS(H6:H1041,$A$6:$A$1041,"w")+SUMIFS(H6:H1041,$A$6:$A$1041,"o")+SUMIFS(H6:H1041,$A$6:$A$1041,"tr")+SUMIFS(H6:H1041,$A$6:$A$1041,"i")+SUMIFS(H6:H1041,$A$6:$A$1041,"tx")+SUMIFS(H6:H1041,$A$6:$A$1041,"mf"))-SUMIFS(H6:H1041,$A$6:$A$1041,"noi") -> 0 | I3: =(SUMIFS(I6:I1041,$A$6:$A$1041,"r")+SUMIFS(I6:I1041,$A$6:$A$1041,"ll")+SUMIFS(I6:I1041,$A$6:$A$1041,"bd")+SUMIFS(I6:I1041,$A$6:$A$1041,"v")+SUMIFS(I6:I1041,$A$6:$A$1041,"nr")+SUMIFS(I6:I1041,$A$6:$A$1041,"oi")+SUMIFS(I6:I1041,$A$6:$A$1041,"rt")+SUMIFS(I6:I1041,$A$6:$A$1041,"ro")+SUMIFS(I6:I1041,$A$6:$A$1041,"rw"))-(SUMIFS(I6:I1041,$A$6:$A$1041,"ad")+SUMIFS(I6:I1041,$A$6:$A$1041,"m")+SUMIFS(I6:I1041,$A$6:$A$1041,"cs")+SUMIFS(I6:I1041,$A$6:$A$1041,"rm")+SUMIFS(I6:I1041,$A$6:$A$1041,"pr")+SUMIFS(I6:I1041,$A$6:$A$1041,"e")+SUMIFS(I6:I1041,$A$6:$A$1041,"w")+SUMIFS(I6:I1041,$A$6:$A$1041,"o")+SUMIFS(I6:I1041,$A$6:$A$1041,"tr")+SUMIFS(I6:I1041,$A$6:$A$1041,"i")+SUMIFS(I6:I1041,$A$6:$A$1041,"tx")+SUMIFS(I6:I1041,$A$6:$A$1041,"mf"))-SUMIFS(I6:I1041,$A$6:$A$1041,"noi") -> 0 | J3: =(SUMIFS(J6:J1041,$A$6:$A$1041,"r")+SUMIFS(J6:J1041,$A$6:$A$1041,"ll")+SUMIFS(J6:J1041,$A$6:$A$1041,"bd")+SUMIFS(J6:J1041,$A$6:$A$1041,"v")+SUMIFS(J6:J1041,$A$6:$A$1041,"nr")+SUMIFS(J6:J1041,$A$6:$A$1041,"oi")+SUMIFS(J6:J1041,$A$6:$A$1041,"rt")+SUMIFS(J6:J1041,$A$6:$A$1041,"ro")+SUMIFS(J6:J1041,$A$6:$A$1041,"rw"))-(SUMIFS(J6:J1041,$A$6:$A$1041,"ad")+SUMIFS(J6:J1041,$A$6:$A$1041,"m")+SUMIFS(J6:J1041,$A$6:$A$1041,"cs")+SUMIFS(J6:J1041,$A$6:$A$1041,"rm")+SUMIFS(J6:J1041,$A$6:$A$1041,"pr")+SUMIFS(J6:J1041,$A$6:$A$1041,"e")+SUMIFS(J6:J1041,$A$6:$A$1041,"w")+SUMIFS(J6:J1041,$A$6:$A$1041,"o")+SUMIFS(J6:J1041,$A$6:$A$1041,"tr")+SUMIFS(J6:J1041,$A$6:$A$1041,"i")+SUMIFS(J6:J1041,$A$6:$A$1041,"tx")+SUMIFS(J6:J1041,$A$6:$A$1041,"mf"))-SUMIFS(J6:J1041,$A$6:$A$1041,"noi") -> 0 | ... O3: =(SUMIFS(O6:O1041,$A$6:$A$1041,"r")+SUMIFS(O6:O1041,$A$6:$A$1041,"ll")+SUMIFS(O6:O1041,$A$6:$A$1041,"bd")+SUMIFS(O6:O1041,$A$6:$A$1041,"v")+SUMIFS(O6:O1041,$A$6:$A$1041,"nr")+SUMIFS(O6:O1041,$A$6:$A$1041,"oi")+SUMIFS(O6:O1041,$A$6:$A$1041,"rt")+SUMIFS(O6:O1041,$A$6:$A$1041,"ro")+SUMIFS(O6:O1041,$A$6:$A$1041,"rw"))-(SUMIFS(O6:O1041,$A$6:$A$1041,"ad")+SUMIFS(O6:O1041,$A$6:$A$1041,"m")+SUMIFS(O6:O1041,$A$6:$A$1041,"cs")+SUMIFS(O6:O1041,$A$6:$A$1041,"rm")+SUMIFS(O6:O1041,$A$6:$A$1041,"pr")+SUMIFS(O6:O1041,$A$6:$A$1041,"e")+SUMIFS(O6:O1041,$A$6:$A$1041,"w")+SUMIFS(O6:O1041,$A$6:$A$1041,"o")+SUMIFS(O6:O1041,$A$6:$A$1041,"tr")+SUMIFS(O6:O1041,$A$6:$A$1041,"i")+SUMIFS(O6:O1041,$A$6:$A$1041,"tx")+SUMIFS(O6:O1041,$A$6:$A$1041,"mf"))-SUMIFS(O6:O1041,$A$6:$A$1041,"noi") -> 0
A4: code | B4: category | C4: date1 | D4: date2 | E4: date3 | F4: date4 | G4: date5 | H4: date6 | I4: date7 | J4: date8 | K4: date9 | L4: date10 | M4: date11 | N4: date12 | O4: total
A5: date | B5: Account | C5: 45809 | D5: 45839 | E5: 45870 | F5: 45901 | G5: 45931 | H5: 45962 | I5: 45992 | J5: 46023 | K5: 46054 | L5: 46082 | M5: 46113 | N5: 46143 | O5: Total | Q5: <-- paste data into here
B6: Revenue
B7: Gross Potential Rent
A8: r | B8: 4100100 Apartment Income | C8: 98319 | D8: 98319 | E8: 98319 | F8: 98319 | G8: 98319 | H8: 98319 | I8: 98319 | J8: 98319 | K8: 98319 | L8: 98319 | M8: 98319 | N8: 98319 | O8: 1179828
A9: ll | B9: 4100101 Gain/Loss to Lease | C9: -7470 | D9: -5694 | E9: -4199 | F9: -3850 | G9: -4278 | H9: -4164 | I9: -4094 | J9: -5332 | K9: -3695 | L9: -3174 | M9: -3385 | N9: -3248 | O9: -52583
B10: Total Potential Rent | C10: 90849 | D10: 92625 | E10: 94120 | F10: 94469 | G10: 94041 | H10: 94155 | I10: 94225 | J10: 92987 | K10: 94624 | L10: 95145 | M10: 94934 | N10: 95071 | O10: 1127245
B11: Apartment Rental Adjustments
A12: v | B12: 4100105 Model Units | C12: 0 | D12: 0 | E12: 0 | F12: 0 | G12: 0 | H12: 0 | I12: 0 | J12: 0 | K12: 0 | L12: 0 | M12: -1.83 | N12: -5 | O12: -6.83
A13: nr | B13: 4100106 Vacancy Loss | C13: -13725.89 | D13: -14532.17 | E13: -25005.29 | F13: -18833.49 | G13: -7135.31 | H13: -3387.5 | I13: -2806.89 | J13: -105.42 | K13: -1181.42 | L13: -2687.1 | M13: -3492.74 | N13: -2583 | O13: -95476.22
A14: nr | B14: 4100107 Concessions | C14: 0 | D14: 0 | E14: 0 | F14: 0 | G14: -99.86 | H14: 0 | I14: 0 | J14: 0 | K14: 0 | L14: 0 | M14: 0 | N14: 0 | O14: -99.86
A15: bd | B15: 4100112 Net Prepaids | C15: 732.09 | D15: 5.94 | E15: -2385.74 | F15: 789.69 | G15: 1159.41 | H15: -2248.45 | I15: 960.86 | J15: 64.26 | K15: -1337.56 | L15: -133.27 | M15: 865.34 | N15: -785.12 | O15: -2312.55
A16: bd | B16: 4100113 Net Delinquency | C16: -7210.84 | D16: -15776.46 | E16: -13010.57 | F16: 1307.36 | G16: -4534.37 | H16: 2586.83 | I16: -1844.19 | J16: -1177.15 | K16: 428.94 | L16: -1032.18 | M16: 66.59 | N16: -368.77 | O16: -40564.81
B17: Total Apartment Rental Adjustments | C17: -20204.64 | D17: -30302.69 | E17: -40401.6 | F17: -16736.44 | G17: -10610.13 | H17: -3049.12 | I17: -3690.22 | J17: -1218.31 | K17: -2090.04 | L17: -3852.55 | M17: -2562.64 | N17: -3741.89 | O17: -138460.27
B18: Total Rental Income | C18: 70644.36 | D18: 62322.31 | E18: 53718.4 | F18: 77732.56 | G18: 83430.87 | H18: 91105.88 | I18: 90534.78 | J18: 91768.69 | K18: 92533.96 | L18: 91292.45 | M18: 92371.36 | N18: 91329.11 | O18: 988784.73
A19: oi | B19: Other Income
A20: oi | B20: 4100200 Month to Month | C20: 0 | D20: 0 | E20: 0 | F20: 0 | G20: 135.89 | H20: 400 | I20: 0 | J20: 0 | K20: 0 | L20: 0 | M20: 0 | N20: 0 | O20: 535.89
A21: oi | B21: 4100600 Cleaning fee/Damage Fee | C21: 0 | D21: 0 | E21: 28.7 | F21: 0 | G21: 0 | H21: 0 | I21: 0 | J21: 0 | K21: 0 | L21: 0 | M21: 0 | N21: 0 | O21: 28.7
A22: oi | B22: 4100700 Carport Parking | C22: 105 | D22: 210 | E22: 105 | F22: 141.17 | G22: 210 | H22: 148.17 | I22: 210 | J22: 175 | K22: 140 | L22: 175 | M22: 175 | N22: 175 | O22: 1969.34
A23: oi | B23: 4100800 Pet Fee | C23: 180 | D23: 180 | E23: 135 | F23: 190 | G23: 145.2 | H23: 120 | I23: 120 | J23: 120 | K23: 145 | L23: 160 | M23: 160 | N23: 185 | O23: 1840.2
A24: oi | B24: 4100900 Deposit Forfeiture | C24: 0 | D24: 4500 | E24: 3499 | F24: 350 | G24: 0 | H24: 0 | I24: 0 | J24: 2440 | K24: 0 | L24: 0 | M24: 404.5 | N24: 718.22 | O24: 11911.72
A25: oi | B25: 4101100 Late Charges | C25: 582 | D25: 339.07 | E25: 64.77 | F25: 949.5 | G25: 410 | H25: 1474 | I25: 969 | J25: 1003.8 | K25: 863.5 | L25: 1166.4 | M25: 104.9 | N25: 629.5 | O25: 8556.44
A26: oi | B26: 4101200 NSF Charges | C26: 50 | D26: 0 | E26: 7 | F26: 93 | G26: 0 | H26: 0 | I26: 100 | J26: 200 | K26: 150 | L26: 50 | M26: 50 | N26: 0 | O26: 700
A27: oi | B27: 4101400 Application Fees | C27: 400 | D27: 390 | E27: 149 | F27: 1347 | G27: 660 | H27: 0 | I27: 75 | J27: 0 | K27: 0 | L27: 225 | M27: 375 | N27: 100 | O27: 3721
A28: oi | B28: 4101500 Washer/Dryer Income | C28: 376.07 | D28: 480 | E28: 318.23 | F28: 952.5 | G28: 1135.2 | H28: 1813.87 | I28: 1627.41 | J28: 1850.61 | K28: 1627.42 | L28: 1600.97 | M28: 1633.17 | N28: 1786.45 | O28: 15201.9
A29: oi | B29: 4101600 Administrative Fee | C29: 420 | D29: 0 | E29: 149 | F29: 637 | G29: 400 | H29: 0 | I29: 0 | J29: 110 | K29: 10 | L29: 110 | M29: 300 | N29: -95 | O29: 2041
A30: rw | B30: 4101800 Water Reimbursement | C30: 0 | D30: 0 | E30: 0 | F30: 0 | G30: 2670 | H30: 4240 | I30: 4151 | J30: 0 | K30: 0 | L30: 0 | M30: 0 | N30: 0 | O30: 11061
A31: rt | B31: 4101830 Trash Reimbursement | C31: 1148.04 | D31: 1127.42 | E31: 818.24 | F31: 919.17 | G31: 760.65 | H31: 705.83 | I31: 760 | J31: 0 | K31: 0 | L31: 0 | M31: 0 | N31: 0 | O31: 6239.35
... A36: oi | B36: 4109000 Amenity Fee | C36: 695 | D36: 730 | E36: 626.96 | F36: 1074.61 | G36: 1002.9 | H36: 1128.34 | I36: 1080 | J36: 1050 | K36: 1085 | L36: 1040 | M36: 1035.68 | N36: 1015 | O36: 11563.49
B37: Total Other Income | C37: 4240.11 | D37: 8332.94 | E37: 6362.21 | F37: 7583.38 | G37: 8683.97 | H37: 11569.14 | I37: 10519.99 | J37: 15122.03 | K37: 12237.13 | L37: 12513.32 | M37: 11116.74 | N37: 11380.13 | O37: 119661.09
A38: rev | B38: Total Revenue | C38: 74884.47 | D38: 70655.25 | E38: 60080.61 | F38: 85315.94 | G38: 92114.84 | H38: 102675.02 | I38: 101054.77 | J38: 106890.72 | K38: 104771.09 | L38: 103805.77 | M38: 103488.1 | N38: 102709.24 | O38: 1108445.8
B39: Operating Expenses
B40: Payroll and Benefits
A41: pr | B41: 5100100 Managers and Assistants | C41: 1341.2 | D41: 1152.2 | E41: 4463.55 | F41: 3231.2 | G41: 3735.21 | H41: 3939.96 | I41: 3627.58 | J41: 5111.93 | K41: 3638.08 | L41: 4464.96 | M41: 3900.58 | N41: 2535.58 | O41: 41142.03
A42: pr | B42: 5100200 Leasing | C42: 0 | D42: 0 | E42: 0 | F42: 0 | G42: 0 | H42: 1277.72 | I42: 0 | J42: 0 | K42: 0 | L42: 0 | M42: 0 | N42: 0 | O42: 1277.72
A43: pr | B43: 5100600 General Maintenance Salaries | C43: 0 | D43: 769.45 | E43: 454.35 | F43: 1214.27 | G43: 214.5 | H43: 3322.8 | I43: 1238.45 | J43: 0 | K43: 390 | L43: 2930.13 | M43: 0 | N43: 1733.56 | O43: 12267.51
A44: pr | B44: 5100900 Incentives | C44: 0 | D44: 400 | E44: 0 | F44: 1800 | G44: 1100 | H44: 600 | I44: 300 | J44: 0 | K44: 480 | L44: 1080 | M44: 120 | N44: 135 | O44: 6015
...

Sheet masterkeytable
A1: code | B1: category | C1: date1 | D1: date2 | E1: date3 | F1: date4 | G1: date5 | H1: date6 | I1: date7 | J1: date8 | K1: date9 | L1: date10 | M1: date11 | N1: date12 | O1: total
B2: Income
A3: r | B3: Rental Income
A4: ll | B4: (Loss to Lease) / Gain to Lease
A5: v | B5: Vacancy
A6: nr | B6: Non-Revenue/Concessions
A7: bd | B7: Bad Debt
A8: rw | B8: RUBS - Water/Sewer
A9: ro | B9: RUBS - Electric/Gas/Other
A10: oi | B10: Other Income
A11: rev | B11: Total Income
B13: Expense
A14: cs | B14: Contract Services
A15: rm | B15: Repair & Maintenance
A16: ad | B16: Administrative
A17: m | B17: Marketing
A18: pr | B18: Payroll
A19: w | B19: Water/Sewer
A20: tr | B20: Trash
A21: e | B21: Electric
A22: o | B22: Gas/Other
A23: mf | B23: Management Fee
A24: i | B24: Insurance
A25: tx | B25: Real Estate Taxes
... A28: noi | B28: Net Operating Income

Sheet Masterkey
B1: Income
A2: r | B2: Rental Income
A3: ll | B3: (Loss to Lease) / Gain to Lease
A4: v | B4: Vacancy
A5: nr | B5: Non-Revenue/Concessions
A6: bd | B6: Bad Debt
A7: rw | B7: RUBS - Water/Sewer
A8: ro | B8: RUBS - Electric/Gas/Other
A9: oi | B9: Other Income
A10: rev | B10: Total Income
B12: Expense
A13: cs | B13: Contract Services
A14: rm | B14: Repair & Maintenance
A15: ad | B15: Administrative
A16: m | B16: Marketing
A17: pr | B17: Payroll
A18: w | B18: Water/Sewer
A19: tr | B19: Trash
A20: e | B20: Electric
A21: o | B21: Gas/Other
A22: mf | B22: Management Fee
A23: i | B23: Insurance
A24: tx | B24: Real Estate Taxes
... A27: noi | B27: Net Operating Income

Sheet Final T-12
A1: code | B1: category | C1: date1 | D1: date2 | E1: date3 | F1: date4 | G1: date5 | H1: date6 | I1: date7 | J1: date8 | K1: date9 | L1: date10 | M1: date11 | N1: date12 | O1: total
A2: date | B2: Account | C2: 45809 | D2: 45839 | E2: 45870 | F2: 45901 | G2: 45931 | H2: 45962 | I2: 45992 | J2: 46023 | K2: 46054 | L2: 46082 | M2: 46113 | N2: 46143 | O2: Total
A4: r | B4: Rental Income
A5: r | B5: 4100100 Apartment Income | C5: 98319 | D5: 98319 | E5: 98319 | F5: 98319 | G5: 98319 | H5: 98319 | I5: 98319 | J5: 98319 | K5: 98319 | L5: 98319 | M5: 98319 | N5: 98319 | O5: 1179828
A6: ll | B6: (Loss to Lease) / Gain to Lease
A7: ll | B7: 4100101 Gain/Loss to Lease | C7: -7470 | D7: -5694 | E7: -4199 | F7: -3850 | G7: -4278 | H7: -4164 | I7: -4094 | J7: -5332 | K7: -3695 | L7: -3174 | M7: -3385 | N7: -3248 | O7: -52583
A8: v | B8: Vacancy
A9: v | B9: 4100105 Model Units | C9: 0 | D9: 0 | E9: 0 | F9: 0 | G9: 0 | H9: 0 | I9: 0 | J9: 0 | K9: 0 | L9: 0 | M9: -1.83 | N9: -5 | O9: -6.83
A10: nr | B10: Non-Revenue/Concessions
A11: nr | B11: 4100106 Vacancy Loss | C11: -13725.89 | D11: -14532.17 | E11: -25005.29 | F11: -18833.49 | G11: -7135.31 | H11: -3387.5 | I11: -2806.89 | J11: -105.42 | K11: -1181.42 | L11: -2687.1 | M11: -3492.74 | N11: -2583 | O11: -95476.22
A12: nr | B12: 4100107 Concessions | C12: 0 | D12: 0 | E12: 0 | F12: 0 | G12: -99.86 | H12: 0 | I12: 0 | J12: 0 | K12: 0 | L12: 0 | M12: 0 | N12: 0 | O12: -99.86
A13: bd | B13: Bad Debt
A14: bd | B14: 4100112 Net Prepaids | C14: 732.09 | D14: 5.94 | E14: -2385.74 | F14: 789.69 | G14: 1159.41 | H14: -2248.45 | I14: 960.86 | J14: 64.26 | K14: -1337.56 | L14: -133.27 | M14: 865.34 | N14: -785.12 | O14: -2312.55
A15: bd | B15: 4100113 Net Delinquency | C15: -7210.84 | D15: -15776.46 | E15: -13010.57 | F15: 1307.36 | G15: -4534.37 | H15: 2586.83 | I15: -1844.19 | J15: -1177.15 | K15: 428.94 | L15: -1032.18 | M15: 66.59 | N15: -368.77 | O15: -40564.81
A16: rw | B16: RUBS - Water/Sewer
A17: rw | B17: 4101800 Water Reimbursement | C17: 0 | D17: 0 | E17: 0 | F17: 0 | G17: 2670 | H17: 4240 | I17: 4151 | J17: 0 | K17: 0 | L17: 0 | M17: 0 | N17: 0 | O17: 11061
A18: ro | B18: RUBS - Electric/Gas/Other
A19: rt | B19: 4101830 Trash Reimbursement | C19: 1148.04 | D19: 1127.42 | E19: 818.24 | F19: 919.17 | G19: 760.65 | H19: 705.83 | I19: 760 | J19: 0 | K19: 0 | L19: 0 | M19: 0 | N19: 0 | O19: 6239.35
A20: oi | B20: Other Income
A21: oi | B21: Other Income | C21: 0 | D21: 0 | E21: 0 | F21: 0 | G21: 0 | H21: 0 | I21: 0 | J21: 0 | K21: 0 | L21: 0 | M21: 0 | N21: 0 | O21: 0
A22: oi | B22: 4100200 Month to Month | C22: 0 | D22: 0 | E22: 0 | F22: 0 | G22: 135.89 | H22: 400 | I22: 0 | J22: 0 | K22: 0 | L22: 0 | M22: 0 | N22: 0 | O22: 535.89
A23: oi | B23: 4100600 Cleaning fee/Damage Fee | C23: 0 | D23: 0 | E23: 28.7 | F23: 0 | G23: 0 | H23: 0 | I23: 0 | J23: 0 | K23: 0 | L23: 0 | M23: 0 | N23: 0 | O23: 28.7
A24: oi | B24: 4100700 Carport Parking | C24: 105 | D24: 210 | E24: 105 | F24: 141.17 | G24: 210 | H24: 148.17 | I24: 210 | J24: 175 | K24: 140 | L24: 175 | M24: 175 | N24: 175 | O24: 1969.34
A25: oi | B25: 4100800 Pet Fee | C25: 180 | D25: 180 | E25: 135 | F25: 190 | G25: 145.2 | H25: 120 | I25: 120 | J25: 120 | K25: 145 | L25: 160 | M25: 160 | N25: 185 | O25: 1840.2
A26: oi | B26: 4100900 Deposit Forfeiture | C26: 0 | D26: 4500 | E26: 3499 | F26: 350 | G26: 0 | H26: 0 | I26: 0 | J26: 2440 | K26: 0 | L26: 0 | M26: 404.5 | N26: 718.22 | O26: 11911.72
A27: oi | B27: 4101100 Late Charges | C27: 582 | D27: 339.07 | E27: 64.77 | F27: 949.5 | G27: 410 | H27: 1474 | I27: 969 | J27: 1003.8 | K27: 863.5 | L27: 1166.4 | M27: 104.9 | N27: 629.5 | O27: 8556.44
A28: oi | B28: 4101200 NSF Charges | C28: 50 | D28: 0 | E28: 7 | F28: 93 | G28: 0 | H28: 0 | I28: 100 | J28: 200 | K28: 150 | L28: 50 | M28: 50 | N28: 0 | O28: 700
A29: oi | B29: 4101400 Application Fees | C29: 400 | D29: 390 | E29: 149 | F29: 1347 | G29: 660 | H29: 0 | I29: 75 | J29: 0 | K29: 0 | L29: 225 | M29: 375 | N29: 100 | O29: 3721
A30: oi | B30: 4101500 Washer/Dryer Income | C30: 376.07 | D30: 480 | E30: 318.23 | F30: 952.5 | G30: 1135.2 | H30: 1813.87 | I30: 1627.41 | J30: 1850.61 | K30: 1627.42 | L30: 1600.97 | M30: 1633.17 | N30: 1786.45 | O30: 15201.9
A31: oi | B31: 4101600 Administrative Fee | C31: 420 | D31: 0 | E31: 149 | F31: 637 | G31: 400 | H31: 0 | I31: 0 | J31: 110 | K31: 10 | L31: 110 | M31: 300 | N31: -95 | O31: 2041
A32: oi | B32: 4101835 Valet Trash Reimbursement | C32: 44.84 | D32: 125.97 | E32: 251.61 | F32: 619.77 | G32: 834.89 | H32: 1166.5 | I32: 1060.48 | J32: 0 | K32: 0 | L32: 0 | M32: 0 | N32: 0 | O32: 4104.06
... A37: rev | B37: Total Revenue | C37: 74884.47 | D37: 70655.25 | E37: 60080.61 | F37: 85315.94 | G37: 92114.84 | H37: 102675.02 | I37: 101054.77 | J37: 106890.72 | K37: 104771.09 | L37: 103805.77 | M37: 103488.1 | N37: 102709.24 | O37: 1108445.8
B39: Expense
A40: cs | B40: Contract Services
A41: cs | B41: 5500200 Equipment Rental and Expense | C41: 0 | D41: 0 | E41: 0 | F41: 0 | G41: 0 | H41: 0 | I41: 1604.27 | J41: 0 | K41: 0 | L41: 0 | M41: 0 | N41: 392 | O41: 1996.27
A42: cs | B42: 5500300 Landscaping | C42: 811.88 | D42: 811.88 | E42: 811.88 | F42: 811.88 | G42: 811.88 | H42: 811.88 | I42: 811.88 | J42: 811.88 | K42: 811.88 | L42: 811.88 | M42: 811.88 | N42: 811.88 | O42: 9742.56
A43: cs | B43: 5500350 Landscaping Seasonal | C43: 0 | D43: 0 | E43: 447.55 | F43: 0 | G43: 0 | H43: 0 | I43: 0 | J43: 0 | K43: 0 | L43: 0 | M43: 0 | N43: 0 | O43: 447.55
A44: cs | B44: 5500700 Pest Control | C44: 0 | D44: 0 | E44: 107.98 | F44: 0 | G44: 363.97 | H44: 107.98 | I44: 107.98 | J44: 118.78 | K44: 0 | L44: 237.56 | M44: 0 | N44: 237.56 | O44: 1281.81
A45: cs | B45: 5500800 Alarm Monitoring | C45: 0 | D45: 0 | E45: 0 | F45: 0 | G45: 0 | H45: 0 | I45: 584.56 | J45: 0 | K45: 681.99 | L45: 2432.06 | M45: 0 | N45: 1694.8 | O45: 5393.41
A46: cs | B46: 5500900 Washer/Dryer Expense | C46: 1203.2 | D46: 1203.2 | E46: 1203.21 | F46: 4690.54 | G46: 0 | H46: 2063.27 | I46: 0 | J46: 1806.42 | K46: 0 | L46: 1815.35 | M46: 3761.86 | N46: 0 | O46: 17747.05
...

Sheet codes
A1: Codes
A3: r | B3: rents
A4: ll | B4: loss to lease
A5: v | B5: vacancy
A6: nr | B6: non-revenue/concessions
A7: bd | B7: bad debt
A8: rw | B8: rubs water
A9: rt | B9: rubs trash
A10: ro | B10: rubs other
A11: oi | B11: other income
A12: rev | B12: revenue
A13: cs | B13: contract services
A14: rm | B14: repairs and maintenance
... A26: noi | B26: net operating income

Sheet Trailing 12 Month Statement
A1: code | B1: category | C1: date1 | D1: date2 | E1: date3 | F1: date4 | G1: date5 | H1: date6 | I1: date7 | J1: date8 | K1: date9 | L1: date10 | M1: date11 | N1: date12 | O1: total
A3: r | B3: Rental Income
A4: r | B4: 4100100 Apartment Income | C4: 98319 | D4: 98319 | E4: 98319 | F4: 98319 | G4: 98319 | H4: 98319 | I4: 98319 | J4: 98319 | K4: 98319 | L4: 98319 | M4: 98319 | N4: 98319 | O4: 1179828
A5: ll | B5: (Loss to Lease) / Gain to Lease
A6: ll | B6: 4100101 Gain/Loss to Lease | C6: -7470 | D6: -5694 | E6: -4199 | F6: -3850 | G6: -4278 | H6: -4164 | I6: -4094 | J6: -5332 | K6: -3695 | L6: -3174 | M6: -3385 | N6: -3248 | O6: -52583
A7: v | B7: Vacancy
A8: v | B8: 4100105 Model Units | C8: 0 | D8: 0 | E8: 0 | F8: 0 | G8: 0 | H8: 0 | I8: 0 | J8: 0 | K8: 0 | L8: 0 | M8: -1.83 | N8: -5 | O8: -6.83
A9: nr | B9: Non-Revenue/Concessions
A10: nr | B10: 4100106 Vacancy Loss | C10: -13725.89 | D10: -14532.17 | E10: -25005.29 | F10: -18833.49 | G10: -7135.31 | H10: -3387.5 | I10: -2806.89 | J10: -105.42 | K10: -1181.42 | L10: -2687.1 | M10: -3492.74 | N10: -2583 | O10: -95476.22
A11: nr | B11: 4100107 Concessions | C11: 0 | D11: 0 | E11: 0 | F11: 0 | G11: -99.86 | H11: 0 | I11: 0 | J11: 0 | K11: 0 | L11: 0 | M11: 0 | N11: 0 | O11: -99.86
A12: bd | B12: Bad Debt
A13: bd | B13: 4100112 Net Prepaids | C13: 732.09 | D13: 5.94 | E13: -2385.74 | F13: 789.69 | G13: 1159.41 | H13: -2248.45 | I13: 960.86 | J13: 64.26 | K13: -1337.56 | L13: -133.27 | M13: 865.34 | N13: -785.12 | O13: -2312.55
A14: bd | B14: 4100113 Net Delinquency | C14: -7210.84 | D14: -15776.46 | E14: -13010.57 | F14: 1307.36 | G14: -4534.37 | H14: 2586.83 | I14: -1844.19 | J14: -1177.15 | K14: 428.94 | L14: -1032.18 | M14: 66.59 | N14: -368.77 | O14: -40564.81
A15: rw | B15: RUBS - Water/Sewer
A16: rw | B16: 4101800 Water Reimbursement | C16: 0 | D16: 0 | E16: 0 | F16: 0 | G16: 2670 | H16: 4240 | I16: 4151 | J16: 0 | K16: 0 | L16: 0 | M16: 0 | N16: 0 | O16: 11061
A17: ro | B17: RUBS - Electric/Gas/Other
A18: rt | B18: 4101830 Trash Reimbursement | C18: 1148.04 | D18: 1127.42 | E18: 818.24 | F18: 919.17 | G18: 760.65 | H18: 705.83 | I18: 760 | J18: 0 | K18: 0 | L18: 0 | M18: 0 | N18: 0 | O18: 6239.35
A19: oi | B19: Other Income
A20: oi | B20: Other Income | C20: 0 | D20: 0 | E20: 0 | F20: 0 | G20: 0 | H20: 0 | I20: 0 | J20: 0 | K20: 0 | L20: 0 | M20: 0 | N20: 0 | O20: 0
A21: oi | B21: 4100200 Month to Month | C21: 0 | D21: 0 | E21: 0 | F21: 0 | G21: 135.89 | H21: 400 | I21: 0 | J21: 0 | K21: 0 | L21: 0 | M21: 0 | N21: 0 | O21: 535.89
A22: oi | B22: 4100600 Cleaning fee/Damage Fee | C22: 0 | D22: 0 | E22: 28.7 | F22: 0 | G22: 0 | H22: 0 | I22: 0 | J22: 0 | K22: 0 | L22: 0 | M22: 0 | N22: 0 | O22: 28.7
A23: oi | B23: 4100700 Carport Parking | C23: 105 | D23: 210 | E23: 105 | F23: 141.17 | G23: 210 | H23: 148.17 | I23: 210 | J23: 175 | K23: 140 | L23: 175 | M23: 175 | N23: 175 | O23: 1969.34
A24: oi | B24: 4100800 Pet Fee | C24: 180 | D24: 180 | E24: 135 | F24: 190 | G24: 145.2 | H24: 120 | I24: 120 | J24: 120 | K24: 145 | L24: 160 | M24: 160 | N24: 185 | O24: 1840.2
A25: oi | B25: 4100900 Deposit Forfeiture | C25: 0 | D25: 4500 | E25: 3499 | F25: 350 | G25: 0 | H25: 0 | I25: 0 | J25: 2440 | K25: 0 | L25: 0 | M25: 404.5 | N25: 718.22 | O25: 11911.72
A26: oi | B26: 4101100 Late Charges | C26: 582 | D26: 339.07 | E26: 64.77 | F26: 949.5 | G26: 410 | H26: 1474 | I26: 969 | J26: 1003.8 | K26: 863.5 | L26: 1166.4 | M26: 104.9 | N26: 629.5 | O26: 8556.44
A27: oi | B27: 4101200 NSF Charges | C27: 50 | D27: 0 | E27: 7 | F27: 93 | G27: 0 | H27: 0 | I27: 100 | J27: 200 | K27: 150 | L27: 50 | M27: 50 | N27: 0 | O27: 700
A28: oi | B28: 4101400 Application Fees | C28: 400 | D28: 390 | E28: 149 | F28: 1347 | G28: 660 | H28: 0 | I28: 75 | J28: 0 | K28: 0 | L28: 225 | M28: 375 | N28: 100 | O28: 3721
A29: oi | B29: 4101500 Washer/Dryer Income | C29: 376.07 | D29: 480 | E29: 318.23 | F29: 952.5 | G29: 1135.2 | H29: 1813.87 | I29: 1627.41 | J29: 1850.61 | K29: 1627.42 | L29: 1600.97 | M29: 1633.17 | N29: 1786.45 | O29: 15201.9
A30: oi | B30: 4101600 Administrative Fee | C30: 420 | D30: 0 | E30: 149 | F30: 637 | G30: 400 | H30: 0 | I30: 0 | J30: 110 | K30: 10 | L30: 110 | M30: 300 | N30: -95 | O30: 2041
A31: oi | B31: 4101835 Valet Trash Reimbursement | C31: 44.84 | D31: 125.97 | E31: 251.61 | F31: 619.77 | G31: 834.89 | H31: 1166.5 | I31: 1060.48 | J31: 0 | K31: 0 | L31: 0 | M31: 0 | N31: 0 | O31: 4104.06
... A36: rev | B36: Total Revenue | C36: 74884.47 | D36: 70655.25 | E36: 60080.61 | F36: 85315.94 | G36: 92114.84 | H36: 102675.02 | I36: 101054.77 | J36: 106890.72 | K36: 104771.09 | L36: 103805.77 | M36: 103488.1 | N36: 102709.24 | O36: 1108445.8
B38: Expense
A39: cs | B39: Contract Services
A40: cs | B40: 5500200 Equipment Rental and Expense | C40: 0 | D40: 0 | E40: 0 | F40: 0 | G40: 0 | H40: 0 | I40: 1604.27 | J40: 0 | K40: 0 | L40: 0 | M40: 0 | N40: 392 | O40: 1996.27
A41: cs | B41: 5500300 Landscaping | C41: 811.88 | D41: 811.88 | E41: 811.88 | F41: 811.88 | G41: 811.88 | H41: 811.88 | I41: 811.88 | J41: 811.88 | K41: 811.88 | L41: 811.88 | M41: 811.88 | N41: 811.88 | O41: 9742.56
A42: cs | B42: 5500350 Landscaping Seasonal | C42: 0 | D42: 0 | E42: 447.55 | F42: 0 | G42: 0 | H42: 0 | I42: 0 | J42: 0 | K42: 0 | L42: 0 | M42: 0 | N42: 0 | O42: 447.55
A43: cs | B43: 5500700 Pest Control | C43: 0 | D43: 0 | E43: 107.98 | F43: 0 | G43: 363.97 | H43: 107.98 | I43: 107.98 | J43: 118.78 | K43: 0 | L43: 237.56 | M43: 0 | N43: 237.56 | O43: 1281.81
A44: cs | B44: 5500800 Alarm Monitoring | C44: 0 | D44: 0 | E44: 0 | F44: 0 | G44: 0 | H44: 0 | I44: 584.56 | J44: 0 | K44: 681.99 | L44: 2432.06 | M44: 0 | N44: 1694.8 | O44: 5393.41
A45: cs | B45: 5500900 Washer/Dryer Expense | C45: 1203.2 | D45: 1203.2 | E45: 1203.21 | F45: 4690.54 | G45: 0 | H45: 2063.27 | I45: 0 | J45: 1806.42 | K45: 0 | L45: 1815.35 | M45: 3761.86 | N45: 0 | O45: 17747.05
A46: rm | B46: Repair & Maintenance
...

Sheet nullvalues
A1: code | B1: category | C1: date1 | D1: date2 | E1: date3 | F1: date4 | G1: date5 | H1: date6 | I1: date7 | J1: date8 | K1: date9 | L1: date10 | M1: date11 | N1: date12 | O1: total

Sheet Sheet3
A1: code | B1: category | C1: date1 | D1: date2 | E1: date3 | F1: date4 | G1: date5 | H1: date6 | I1: date7 | J1: date8 | K1: date9 | L1: date10 | M1: date11 | N1: date12 | O1: total
